Workbook

Sheet Kedge P&L, Burn & Runway
A1: Kedge P&L, Burn & Runway
A2: Operating Model · Stress: Sonnet on big repos
A4: Variable / dimension | B4: 2026-10 | C4: 2026-11 | D4: 2026-12 | E4: 2027-01 | F4: 2027-02 | G4: 2027-03 | H4: 2027-04 | I4: 2027-05 | J4: 2027-06 | K4: 2027-07 | L4: 2027-08 | M4: 2027-09 | N4: 2027-10 | O4: 2027-11 | P4: 2027-12 | Q4: 2028-01 | R4: 2028-02 | S4: 2028-03 | T4: 2028-04 | U4: 2028-05 | V4: 2028-06 | W4: 2028-07 | X4: 2028-08 | Y4: 2028-09
A5: Revenue | B5: ='Model inputs'!C16*'Model inputs'!AA25 -> 600 | C5: ='Model inputs'!D16*'Model inputs'!AA25 -> 1090.9091 | D5: ='Model inputs'!E16*'Model inputs'!AA25 -> 1581.8182 | E5: ='Model inputs'!F16*'Model inputs'!AA25 -> 2072.7273 | F5: ='Model inputs'!G16*'Model inputs'!AA25 -> 2563.6364 | G5: ='Model inputs'!H16*'Model inputs'!AA25 -> 3054.5455 | H5: ='Model inputs'!I16*'Model inputs'!AA25 -> 3545.4545 | I5: ='Model inputs'!J16*'Model inputs'!AA25 -> 4036.3636 | J5: ='Model inputs'!K16*'Model inputs'!AA25 -> 4527.2727 | K5: ='Model inputs'!L16*'Model inputs'!AA25 -> 5018.1818 | L5: ='Model inputs'!M16*'Model inputs'!AA25 -> 5509.0909 | M5: ='Model inputs'!N16*'Model inputs'!AA25 -> 6000 | N5: ='Model inputs'!O16*'Model inputs'!AA25 -> 6000 | O5: ='Model inputs'!P16*'Model inputs'!AA25 -> 6000 | P5: ='Model inputs'!Q16*'Model inputs'!AA25 -> 6000 | Q5: ='Model inputs'!R16*'Model inputs'!AA25 -> 6000 | R5: ='Model inputs'!S16*'Model inputs'!AA25 -> 6000 | S5: ='Model inputs'!T16*'Model inputs'!AA25 -> 6000 | T5: ='Model inputs'!U16*'Model inputs'!AA25 -> 6000 | U5: ='Model inputs'!V16*'Model inputs'!AA25 -> 6000 | V5: ='Model inputs'!W16*'Model inputs'!AA25 -> 6000 | W5: ='Model inputs'!X16*'Model inputs'!AA25 -> 6000 | X5: ='Model inputs'!Y16*'Model inputs'!AA25 -> 6000 | Y5: ='Model inputs'!Z16*'Model inputs'!AA25 -> 6000
A6: AI model costs | B6: ='Model inputs'!C16*'Model inputs'!AA18 -> 171 | C6: ='Model inputs'!D16*'Model inputs'!AA18 -> 310.90909 | D6: ='Model inputs'!E16*'Model inputs'!AA18 -> 450.81818 | E6: ='Model inputs'!F16*'Model inputs'!AA18 -> 590.72727 | F6: ='Model inputs'!G16*'Model inputs'!AA18 -> 730.63636 | G6: ='Model inputs'!H16*'Model inputs'!AA18 -> 870.54545 | H6: ='Model inputs'!I16*'Model inputs'!AA18 -> 1010.4545 | I6: ='Model inputs'!J16*'Model inputs'!AA18 -> 1150.3636 | J6: ='Model inputs'!K16*'Model inputs'!AA18 -> 1290.2727 | K6: ='Model inputs'!L16*'Model inputs'!AA18 -> 1430.1818 | L6: ='Model inputs'!M16*'Model inputs'!AA18 -> 1570.0909 | M6: ='Model inputs'!N16*'Model inputs'!AA18 -> 1710 | N6: ='Model inputs'!O16*'Model inputs'!AA18 -> 1710 | O6: ='Model inputs'!P16*'Model inputs'!AA18 -> 1710 | P6: ='Model inputs'!Q16*'Model inputs'!AA18 -> 1710 | Q6: ='Model inputs'!R16*'Model inputs'!AA18 -> 1710 | R6: ='Model inputs'!S16*'Model inputs'!AA18 -> 1710 | S6: ='Model inputs'!T16*'Model inputs'!AA18 -> 1710 | T6: ='Model inputs'!U16*'Model inputs'!AA18 -> 1710 | U6: ='Model inputs'!V16*'Model inputs'!AA18 -> 1710 | V6: ='Model inputs'!W16*'Model inputs'!AA18 -> 1710 | W6: ='Model inputs'!X16*'Model inputs'!AA18 -> 1710 | X6: ='Model inputs'!Y16*'Model inputs'!AA18 -> 1710 | Y6: ='Model inputs'!Z16*'Model inputs'!AA18 -> 1710
A7: Payment processing | B7: ='Kedge P&L, Burn & Runway'!B5*'Model inputs'!AA24 -> 18 | C7: ='Kedge P&L, Burn & Runway'!C5*'Model inputs'!AA24 -> 32.727273 | D7: ='Kedge P&L, Burn & Runway'!D5*'Model inputs'!AA24 -> 47.454545 | E7: ='Kedge P&L, Burn & Runway'!E5*'Model inputs'!AA24 -> 62.181818 | F7: ='Kedge P&L, Burn & Runway'!F5*'Model inputs'!AA24 -> 76.909091 | G7: ='Kedge P&L, Burn & Runway'!G5*'Model inputs'!AA24 -> 91.636364 | H7: ='Kedge P&L, Burn & Runway'!H5*'Model inputs'!AA24 -> 106.36364 | I7: ='Kedge P&L, Burn & Runway'!I5*'Model inputs'!AA24 -> 121.09091 | J7: ='Kedge P&L, Burn & Runway'!J5*'Model inputs'!AA24 -> 135.81818 | K7: ='Kedge P&L, Burn & Runway'!K5*'Model inputs'!AA24 -> 150.54545 | L7: ='Kedge P&L, Burn & Runway'!L5*'Model inputs'!AA24 -> 165.27273 | M7: ='Kedge P&L, Burn & Runway'!M5*'Model inputs'!AA24 -> 180 | N7: ='Kedge P&L, Burn & Runway'!N5*'Model inputs'!AA24 -> 180 | O7: ='Kedge P&L, Burn & Runway'!O5*'Model inputs'!AA24 -> 180 | P7: ='Kedge P&L, Burn & Runway'!P5*'Model inputs'!AA24 -> 180 | Q7: ='Kedge P&L, Burn & Runway'!Q5*'Model inputs'!AA24 -> 180 | R7: ='Kedge P&L, Burn & Runway'!R5*'Model inputs'!AA24 -> 180 | S7: ='Kedge P&L, Burn & Runway'!S5*'Model inputs'!AA24 -> 180 | T7: ='Kedge P&L, Burn & Runway'!T5*'Model inputs'!AA24 -> 180 | U7: ='Kedge P&L, Burn & Runway'!U5*'Model inputs'!AA24 -> 180 | V7: ='Kedge P&L, Burn & Runway'!V5*'Model inputs'!AA24 -> 180 | W7: ='Kedge P&L, Burn & Runway'!W5*'Model inputs'!AA24 -> 180 | X7: ='Kedge P&L, Burn & Runway'!X5*'Model inputs'!AA24 -> 180 | Y7: ='Kedge P&L, Burn & Runway'!Y5*'Model inputs'!AA24 -> 180
A8: Cost of goods sold | B8: ='Kedge P&L, Burn & Runway'!B6+'Kedge P&L, Burn & Runway'!B7 -> 189 | C8: ='Kedge P&L, Burn & Runway'!C6+'Kedge P&L, Burn & Runway'!C7 -> 343.63636 | D8: ='Kedge P&L, Burn & Runway'!D6+'Kedge P&L, Burn & Runway'!D7 -> 498.27273 | E8: ='Kedge P&L, Burn & Runway'!E6+'Kedge P&L, Burn & Runway'!E7 -> 652.90909 | F8: ='Kedge P&L, Burn & Runway'!F6+'Kedge P&L, Burn & Runway'!F7 -> 807.54545 | G8: ='Kedge P&L, Burn & Runway'!G6+'Kedge P&L, Burn & Runway'!G7 -> 962.18182 | H8: ='Kedge P&L, Burn & Runway'!H6+'Kedge P&L, Burn & Runway'!H7 -> 1116.8182 | I8: ='Kedge P&L, Burn & Runway'!I6+'Kedge P&L, Burn & Runway'!I7 -> 1271.4545 | ... Y8: ='Kedge P&L, Burn & Runway'!Y6+'Kedge P&L, Burn & Runway'!Y7 -> 1890
A9: Gross profit | B9: ='Kedge P&L, Burn & Runway'!B5-'Kedge P&L, Burn & Runway'!B8 -> 411 | C9: ='Kedge P&L, Burn & Runway'!C5-'Kedge P&L, Burn & Runway'!C8 -> 747.27273 | D9: ='Kedge P&L, Burn & Runway'!D5-'Kedge P&L, Burn & Runway'!D8 -> 1083.5455 | E9: ='Kedge P&L, Burn & Runway'!E5-'Kedge P&L, Burn & Runway'!E8 -> 1419.8182 | F9: ='Kedge P&L, Burn & Runway'!F5-'Kedge P&L, Burn & Runway'!F8 -> 1756.0909 | G9: ='Kedge P&L, Burn & Runway'!G5-'Kedge P&L, Burn & Runway'!G8 -> 2092.3636 | H9: ='Kedge P&L, Burn & Runway'!H5-'Kedge P&L, Burn & Runway'!H8 -> 2428.6364 | I9: ='Kedge P&L, Burn & Runway'!I5-'Kedge P&L, Burn & Runway'!I8 -> 2764.9091 | ... Y9: ='Kedge P&L, Burn & Runway'!Y5-'Kedge P&L, Burn & Runway'!Y8 -> 4110
A10: Gross margin | B10: =IFERROR('Kedge P&L, Burn & Runway'!B9/'Kedge P&L, Burn & Runway'!B5,"") -> 0.685 | C10: =IFERROR('Kedge P&L, Burn & Runway'!C9/'Kedge P&L, Burn & Runway'!C5,"") -> 0.685 | D10: =IFERROR('Kedge P&L, Burn & Runway'!D9/'Kedge P&L, Burn & Runway'!D5,"") -> 0.685 | E10: =IFERROR('Kedge P&L, Burn & Runway'!E9/'Kedge P&L, Burn & Runway'!E5,"") -> 0.685 | F10: =IFERROR('Kedge P&L, Burn & Runway'!F9/'Kedge P&L, Burn & Runway'!F5,"") -> 0.685 | G10: =IFERROR('Kedge P&L, Burn & Runway'!G9/'Kedge P&L, Burn & Runway'!G5,"") -> 0.685 | H10: =IFERROR('Kedge P&L, Burn & Runway'!H9/'Kedge P&L, Burn & Runway'!H5,"") -> 0.685 | I10: =IFERROR('Kedge P&L, Burn & Runway'!I9/'Kedge P&L, Burn & Runway'!I5,"") -> 0.685 | ... Y10: =IFERROR('Kedge P&L, Burn & Runway'!Y9/'Kedge P&L, Burn & Runway'!Y5,"") -> 0.685
A11: Founder salaries | B11: =IF(IF(IF(ISERROR('Model inputs'!C19>'Model inputs'!AA31),'Model inputs'!C19>'Model inputs'!AA31,IF(OR('Model inputs'!C19="",'Model inputs'!AA31=""),"",'Model inputs'!C19>'Model inputs'!AA31))="",FALSE,IF(ISERROR('Model inputs'!C19>'Model inputs'!AA31),'Model inputs'!C19>'Model inputs'!AA31,IF(OR('Model inputs'!C19="",'Model inputs'!AA31=""),"",'Model inputs'!C19>'Model inputs'!AA31))),'Model inputs'!AA13*'Model inputs'!AA11,0) -> 0 | C11: =IF(IF(IF(ISERROR('Model inputs'!D19>'Model inputs'!AA31),'Model inputs'!D19>'Model inputs'!AA31,IF(OR('Model inputs'!D19="",'Model inputs'!AA31=""),"",'Model inputs'!D19>'Model inputs'!AA31))="",FALSE,IF(ISERROR('Model inputs'!D19>'Model inputs'!AA31),'Model inputs'!D19>'Model inputs'!AA31,IF(OR('Model inputs'!D19="",'Model inputs'!AA31=""),"",'Model inputs'!D19>'Model inputs'!AA31))),'Model inputs'!AA13*'Model inputs'!AA11,0) -> 0 | D11: =IF(IF(IF(ISERROR('Model inputs'!E19>'Model inputs'!AA31),'Model inputs'!E19>'Model inputs'!AA31,IF(OR('Model inputs'!E19="",'Model inputs'!AA31=""),"",'Model inputs'!E19>'Model inputs'!AA31))="",FALSE,IF(ISERROR('Model inputs'!E19>'Model inputs'!AA31),'Model inputs'!E19>'Model inputs'!AA31,IF(OR('Model inputs'!E19="",'Model inputs'!AA31=""),"",'Model inputs'!E19>'Model inputs'!AA31))),'Model inputs'!AA13*'Model inputs'!AA11,0) -> 0 | E11: =IF(IF(IF(ISERROR('Model inputs'!F19>'Model inputs'!AA31),'Model inputs'!F19>'Model inputs'!AA31,IF(OR('Model inputs'!F19="",'Model inputs'!AA31=""),"",'Model inputs'!F19>'Model inputs'!AA31))="",FALSE,IF(ISERROR('Model inputs'!F19>'Model inputs'!AA31),'Model inputs'!F19>'Model inputs'!AA31,IF(OR('Model inputs'!F19="",'Model inputs'!AA31=""),"",'Model inputs'!F19>'Model inputs'!AA31))),'Model inputs'!AA13*'Model inputs'!AA11,0) -> 0 | F11: =IF(IF(IF(ISERROR('Model inputs'!G19>'Model inputs'!AA31),'Model inputs'!G19>'Model inputs'!AA31,IF(OR('Model inputs'!G19="",'Model inputs'!AA31=""),"",'Model inputs'!G19>'Model inputs'!AA31))="",FALSE,IF(ISERROR('Model inputs'!G19>'Model inputs'!AA31),'Model inputs'!G19>'Model inputs'!AA31,IF(OR('Model inputs'!G19="",'Model inputs'!AA31=""),"",'Model inputs'!G19>'Model inputs'!AA31))),'Model inputs'!AA13*'Model inputs'!AA11,0) -> 0 | G11: =IF(IF(IF(ISERROR('Model inputs'!H19>'Model inputs'!AA31),'Model inputs'!H19>'Model inputs'!AA31,IF(OR('Model inputs'!H19="",'Model inputs'!AA31=""),"",'Model inputs'!H19>'Model inputs'!AA31))="",FALSE,IF(ISERROR('Model inputs'!H19>'Model inputs'!AA31),'Model inputs'!H19>'Model inputs'!AA31,IF(OR('Model inputs'!H19="",'Model inputs'!AA31=""),"",'Model inputs'!H19>'Model inputs'!AA31))),'Model inputs'!AA13*'Model inputs'!AA11,0) -> 0 | H11: =IF(IF(IF(ISERROR('Model inputs'!I19>'Model inputs'!AA31),'Model inputs'!I19>'Model inputs'!AA31,IF(OR('Model inputs'!I19="",'Model inputs'!AA31=""),"",'Model inputs'!I19>'Model inputs'!AA31))="",FALSE,IF(ISERROR('Model inputs'!I19>'Model inputs'!AA31),'Model inputs'!I19>'Model inputs'!AA31,IF(OR('Model inputs'!I19="",'Model inputs'!AA31=""),"",'Model inputs'!I19>'Model inputs'!AA31))),'Model inputs'!AA13*'Model inputs'!AA11,0) -> 8000 | I11: =IF(IF(IF(ISERROR('Model inputs'!J19>'Model inputs'!AA31),'Model inputs'!J19>'Model inputs'!AA31,IF(OR('Model inputs'!J19="",'Model inputs'!AA31=""),"",'Model inputs'!J19>'Model inputs'!AA31))="",FALSE,IF(ISERROR('Model inputs'!J19>'Model inputs'!AA31),'Model inputs'!J19>'Model inputs'!AA31,IF(OR('Model inputs'!J19="",'Model inputs'!AA31=""),"",'Model inputs'!J19>'Model inputs'!AA31))),'Model inputs'!AA13*'Model inputs'!AA11,0) -> 8000 | J11: =IF(IF(IF(ISERROR('Model inputs'!K19>'Model inputs'!AA31),'Model inputs'!K19>'Model inputs'!AA31,IF(OR('Model inputs'!K19="",'Model inputs'!AA31=""),"",'Model inputs'!K19>'Model inputs'!AA31))="",FALSE,IF(ISERROR('Model inputs'!K19>'Model inputs'!AA31),'Model inputs'!K19>'Model inputs'!AA31,IF(OR('Model inputs'!K19="",'Model inputs'!AA31=""),"",'Model inputs'!K19>'Model inputs'!AA31))),'Model inputs'!AA13*'Model inputs'!AA11,0) -> 8000 | K11: =IF(IF(IF(ISERROR('Model inputs'!L19>'Model inputs'!AA31),'Model inputs'!L19>'Model inputs'!AA31,IF(OR('Model inputs'!L19="",'Model inputs'!AA31=""),"",'Model inputs'!L19>'Model inputs'!AA31))="",FALSE,IF(ISERROR('Model inputs'!L19>'Model inputs'!AA31),'Model inputs'!L19>'Model inputs'!AA31,IF(OR('Model inputs'!L19="",'Model inputs'!AA31=""),"",'Model inputs'!L19>'Model inputs'!AA31))),'Model inputs'!AA13*'Model inputs'!AA11,0) -> 8000 | L11: =IF(IF(IF(ISERROR('Model inputs'!M19>'Model inputs'!AA31),'Model inputs'!M19>'Model inputs'!AA31,IF(OR('Model inputs'!M19="",'Model inputs'!AA31=""),"",'Model inputs'!M19>'Model inputs'!AA31))="",FALSE,IF(ISERROR('Model inputs'!M19>'Model inputs'!AA31),'Model inputs'!M19>'Model inputs'!AA31,IF(OR('Model inputs'!M19="",'Model inputs'!AA31=""),"",'Model inputs'!M19>'Model inputs'!AA31))),'Model inputs'!AA13*'Model inputs'!AA11,0) -> 8000 | M11: =IF(IF(IF(ISERROR('Model inputs'!N19>'Model inputs'!AA31),'Model inputs'!N19>'Model inputs'!AA31,IF(OR('Model inputs'!N19="",'Model inputs'!AA31=""),"",'Model inputs'!N19>'Model inputs'!AA31))="",FALSE,IF(ISERROR('Model inputs'!N19>'Model inputs'!AA31),'Model inputs'!N19>'Model inputs'!AA31,IF(OR('Model inputs'!N19="",'Model inputs'!AA31=""),"",'Model inputs'!N19>'Model inputs'!AA31))),'Model inputs'!AA13*'Model inputs'!AA11,0) -> 8000 | N11: =IF(IF(IF(ISERROR('Model inputs'!O19>'Model inputs'!AA31),'Model inputs'!O19>'Model inputs'!AA31,IF(OR('Model inputs'!O19="",'Model inputs'!AA31=""),"",'Model inputs'!O19>'Model inputs'!AA31))="",FALSE,IF(ISERROR('Model inputs'!O19>'Model inputs'!AA31),'Model inputs'!O19>'Model inputs'!AA31,IF(OR('Model inputs'!O19="",'Model inputs'!AA31=""),"",'Model inputs'!O19>'Model inputs'!AA31))),'Model inputs'!AA13*'Model inputs'!AA11,0) -> 8000 | O11: =IF(IF(IF(ISERROR('Model inputs'!P19>'Model inputs'!AA31),'Model inputs'!P19>'Model inputs'!AA31,IF(OR('Model inputs'!P19="",'Model inputs'!AA31=""),"",'Model inputs'!P19>'Model inputs'!AA31))="",FALSE,IF(ISERROR('Model inputs'!P19>'Model inputs'!AA31),'Model inputs'!P19>'Model inputs'!AA31,IF(OR('Model inputs'!P19="",'Model inputs'!AA31=""),"",'Model inputs'!P19>'Model inputs'!AA31))),'Model inputs'!AA13*'Model inputs'!AA11,0) -> 8000 | P11: =IF(IF(IF(ISERROR('Model inputs'!Q19>'Model inputs'!AA31),'Model inputs'!Q19>'Model inputs'!AA31,IF(OR('Model inputs'!Q19="",'Model inputs'!AA31=""),"",'Model inputs'!Q19>'Model inputs'!AA31))="",FALSE,IF(ISERROR('Model inputs'!Q19>'Model inputs'!AA31),'Model inputs'!Q19>'Model inputs'!AA31,IF(OR('Model inputs'!Q19="",'Model inputs'!AA31=""),"",'Model inputs'!Q19>'Model inputs'!AA31))),'Model inputs'!AA13*'Model inputs'!AA11,0) -> 8000 | Q11: =IF(IF(IF(ISERROR('Model inputs'!R19>'Model inputs'!AA31),'Model inputs'!R19>'Model inputs'!AA31,IF(OR('Model inputs'!R19="",'Model inputs'!AA31=""),"",'Model inputs'!R19>'Model inputs'!AA31))="",FALSE,IF(ISERROR('Model inputs'!R19>'Model inputs'!AA31),'Model inputs'!R19>'Model inputs'!AA31,IF(OR('Model inputs'!R19="",'Model inputs'!AA31=""),"",'Model inputs'!R19>'Model inputs'!AA31))),'Model inputs'!AA13*'Model inputs'!AA11,0) -> 8000 | R11: =IF(IF(IF(ISERROR('Model inputs'!S19>'Model inputs'!AA31),'Model inputs'!S19>'Model inputs'!AA31,IF(OR('Model inputs'!S19="",'Model inputs'!AA31=""),"",'Model inputs'!S19>'Model inputs'!AA31))="",FALSE,IF(ISERROR('Model inputs'!S19>'Model inputs'!AA31),'Model inputs'!S19>'Model inputs'!AA31,IF(OR('Model inputs'!S19="",'Model inputs'!AA31=""),"",'Model inputs'!S19>'Model inputs'!AA31))),'Model inputs'!AA13*'Model inputs'!AA11,0) -> 8000 | S11: =IF(IF(IF(ISERROR('Model inputs'!T19>'Model inputs'!AA31),'Model inputs'!T19>'Model inputs'!AA31,IF(OR('Model inputs'!T19="",'Model inputs'!AA31=""),"",'Model inputs'!T19>'Model inputs'!AA31))="",FALSE,IF(ISERROR('Model inputs'!T19>'Model inputs'!AA31),'Model inputs'!T19>'Model inputs'!AA31,IF(OR('Model inputs'!T19="",'Model inputs'!AA31=""),"",'Model inputs'!T19>'Model inputs'!AA31))),'Model inputs'!AA13*'Model inputs'!AA11,0) -> 8000 | T11: =IF(IF(IF(ISERROR('Model inputs'!U19>'Model inputs'!AA31),'Model inputs'!U19>'Model inputs'!AA31,IF(OR('Model inputs'!U19="",'Model inputs'!AA31=""),"",'Model inputs'!U19>'Model inputs'!AA31))="",FALSE,IF(ISERROR('Model inputs'!U19>'Model inputs'!AA31),'Model inputs'!U19>'Model inputs'!AA31,IF(OR('Model inputs'!U19="",'Model inputs'!AA31=""),"",'Model inputs'!U19>'Model inputs'!AA31))),'Model inputs'!AA13*'Model inputs'!AA11,0) -> 8000 | U11: =IF(IF(IF(ISERROR('Model inputs'!V19>'Model inputs'!AA31),'Model inputs'!V19>'Model inputs'!AA31,IF(OR('Model inputs'!V19="",'Model inputs'!AA31=""),"",'Model inputs'!V19>'Model inputs'!AA31))="",FALSE,IF(ISERROR('Model inputs'!V19>'Model inputs'!AA31),'Model inputs'!V19>'Model inputs'!AA31,IF(OR('Model inputs'!V19="",'Model inputs'!AA31=""),"",'Model inputs'!V19>'Model inputs'!AA31))),'Model inputs'!AA13*'Model inputs'!AA11,0) -> 8000 | V11: =IF(IF(IF(ISERROR('Model inputs'!W19>'Model inputs'!AA31),'Model inputs'!W19>'Model inputs'!AA31,IF(OR('Model inputs'!W19="",'Model inputs'!AA31=""),"",'Model inputs'!W19>'Model inputs'!AA31))="",FALSE,IF(ISERROR('Model inputs'!W19>'Model inputs'!AA31),'Model inputs'!W19>'Model inputs'!AA31,IF(OR('Model inputs'!W19="",'Model inputs'!AA31=""),"",'Model inputs'!W19>'Model inputs'!AA31))),'Model inputs'!AA13*'Model inputs'!AA11,0) -> 8000 | W11: =IF(IF(IF(ISERROR('Model inputs'!X19>'Model inputs'!AA31),'Model inputs'!X19>'Model inputs'!AA31,IF(OR('Model inputs'!X19="",'Model inputs'!AA31=""),"",'Model inputs'!X19>'Model inputs'!AA31))="",FALSE,IF(ISERROR('Model inputs'!X19>'Model inputs'!AA31),'Model inputs'!X19>'Model inputs'!AA31,IF(OR('Model inputs'!X19="",'Model inputs'!AA31=""),"",'Model inputs'!X19>'Model inputs'!AA31))),'Model inputs'!AA13*'Model inputs'!AA11,0) -> 8000 | X11: =IF(IF(IF(ISERROR('Model inputs'!Y19>'Model inputs'!AA31),'Model inputs'!Y19>'Model inputs'!AA31,IF(OR('Model inputs'!Y19="",'Model inputs'!AA31=""),"",'Model inputs'!Y19>'Model inputs'!AA31))="",FALSE,IF(ISERROR('Model inputs'!Y19>'Model inputs'!AA31),'Model inputs'!Y19>'Model inputs'!AA31,IF(OR('Model inputs'!Y19="",'Model inputs'!AA31=""),"",'Model inputs'!Y19>'Model inputs'!AA31))),'Model inputs'!AA13*'Model inputs'!AA11,0) -> 8000 | Y11: =IF(IF(IF(ISERROR('Model inputs'!Z19>'Model inputs'!AA31),'Model inputs'!Z19>'Model inputs'!AA31,IF(OR('Model inputs'!Z19="",'Model inputs'!AA31=""),"",'Model inputs'!Z19>'Model inputs'!AA31))="",FALSE,IF(ISERROR('Model inputs'!Z19>'Model inputs'!AA31),'Model inputs'!Z19>'Model inputs'!AA31,IF(OR('Model inputs'!Z19="",'Model inputs'!AA31=""),"",'Model inputs'!Z19>'Model inputs'!AA31))),'Model inputs'!AA13*'Model inputs'!AA11,0) -> 8000
A12: Software and tools | B12: =IF('Model inputs'!AA29="","",'Model inputs'!AA29) -> 200 | C12: =IF('Model inputs'!AA29="","",'Model inputs'!AA29) -> 200 | D12: =IF('Model inputs'!AA29="","",'Model inputs'!AA29) -> 200 | E12: =IF('Model inputs'!AA29="","",'Model inputs'!AA29) -> 200 | F12: =IF('Model inputs'!AA29="","",'Model inputs'!AA29) -> 200 | G12: =IF('Model inputs'!AA29="","",'Model inputs'!AA29) -> 200 | H12: =IF('Model inputs'!AA29="","",'Model inputs'!AA29) -> 200 | I12: =IF('Model inputs'!AA29="","",'Model inputs'!AA29) -> 200 | J12: =IF('Model inputs'!AA29="","",'Model inputs'!AA29) -> 200 | K12: =IF('Model inputs'!AA29="","",'Model inputs'!AA29) -> 200 | L12: =IF('Model inputs'!AA29="","",'Model inputs'!AA29) -> 200 | M12: =IF('Model inputs'!AA29="","",'Model inputs'!AA29) -> 200 | N12: =IF('Model inputs'!AA29="","",'Model inputs'!AA29) -> 200 | O12: =IF('Model inputs'!AA29="","",'Model inputs'!AA29) -> 200 | P12: =IF('Model inputs'!AA29="","",'Model inputs'!AA29) -> 200 | Q12: =IF('Model inputs'!AA29="","",'Model inputs'!AA29) -> 200 | R12: =IF('Model inputs'!AA29="","",'Model inputs'!AA29) -> 200 | S12: =IF('Model inputs'!AA29="","",'Model inputs'!AA29) -> 200 | T12: =IF('Model inputs'!AA29="","",'Model inputs'!AA29) -> 200 | U12: =IF('Model inputs'!AA29="","",'Model inputs'!AA29) -> 200 | V12: =IF('Model inputs'!AA29="","",'Model inputs'!AA29) -> 200 | W12: =IF('Model inputs'!AA29="","",'Model inputs'!AA29) -> 200 | X12: =IF('Model inputs'!AA29="","",'Model inputs'!AA29) -> 200 | Y12: =IF('Model inputs'!AA29="","",'Model inputs'!AA29) -> 200
A13: Operating expenses | B13: ='Kedge P&L, Burn & Runway'!B11+'Kedge P&L, Burn & Runway'!B12 -> 200 | C13: ='Kedge P&L, Burn & Runway'!C11+'Kedge P&L, Burn & Runway'!C12 -> 200 | D13: ='Kedge P&L, Burn & Runway'!D11+'Kedge P&L, Burn & Runway'!D12 -> 200 | E13: ='Kedge P&L, Burn & Runway'!E11+'Kedge P&L, Burn & Runway'!E12 -> 200 | F13: ='Kedge P&L, Burn & Runway'!F11+'Kedge P&L, Burn & Runway'!F12 -> 200 | G13: ='Kedge P&L, Burn & Runway'!G11+'Kedge P&L, Burn & Runway'!G12 -> 200 | H13: ='Kedge P&L, Burn & Runway'!H11+'Kedge P&L, Burn & Runway'!H12 -> 8200 | I13: ='Kedge P&L, Burn & Runway'!I11+'Kedge P&L, Burn & Runway'!I12 -> 8200 | ... Y13: ='Kedge P&L, Burn & Runway'!Y11+'Kedge P&L, Burn & Runway'!Y12 -> 8200
A14: Operating income | B14: ='Kedge P&L, Burn & Runway'!B9-'Kedge P&L, Burn & Runway'!B13 -> 211 | C14: ='Kedge P&L, Burn & Runway'!C9-'Kedge P&L, Burn & Runway'!C13 -> 547.27273 | D14: ='Kedge P&L, Burn & Runway'!D9-'Kedge P&L, Burn & Runway'!D13 -> 883.54545 | E14: ='Kedge P&L, Burn & Runway'!E9-'Kedge P&L, Burn & Runway'!E13 -> 1219.8182 | F14: ='Kedge P&L, Burn & Runway'!F9-'Kedge P&L, Burn & Runway'!F13 -> 1556.0909 | G14: ='Kedge P&L, Burn & Runway'!G9-'Kedge P&L, Burn & Runway'!G13 -> 1892.3636 | H14: ='Kedge P&L, Burn & Runway'!H9-'Kedge P&L, Burn & Runway'!H13 -> -5771.3636 | I14: ='Kedge P&L, Burn & Runway'!I9-'Kedge P&L, Burn & Runway'!I13 -> -5435.0909 | ... Y14: ='Kedge P&L, Burn & Runway'!Y9-'Kedge P&L, Burn & Runway'!Y13 -> -4090
A15: Net burn | B15: =-'Kedge P&L, Burn & Runway'!B14 -> -211 | C15: =-'Kedge P&L, Burn & Runway'!C14 -> -547.27273 | D15: =-'Kedge P&L, Burn & Runway'!D14 -> -883.54545 | E15: =-'Kedge P&L, Burn & Runway'!E14 -> -1219.8182 | F15: =-'Kedge P&L, Burn & Runway'!F14 -> -1556.0909 | G15: =-'Kedge P&L, Burn & Runway'!G14 -> -1892.3636 | H15: =-'Kedge P&L, Burn & Runway'!H14 -> 5771.3636 | I15: =-'Kedge P&L, Burn & Runway'!I14 -> 5435.0909 | ... Y15: =-'Kedge P&L, Burn & Runway'!Y14 -> 4090
A16: Equity raised | B16: 0 | C16: 0 | D16: 0 | E16: 0 | F16: 0 | G16: 0 | H16: =60000 -> 60000 | I16: 0 | J16: 0 | K16: 0 | L16: 0 | M16: 0 | N16: 0 | O16: 0 | P16: 0 | Q16: 0 | R16: 0 | S16: 0 | T16: 0 | U16: 0 | V16: 0 | W16: 0 | X16: 0 | Y16: 0
A17: Cash balance | B17: ='Model inputs'!B7-'Kedge P&L, Burn & Runway'!B15+'Kedge P&L, Burn & Runway'!B16 -> 211 | C17: ='Kedge P&L, Burn & Runway'!B17-'Kedge P&L, Burn & Runway'!C15+'Kedge P&L, Burn & Runway'!C16 -> 758.27273 | D17: ='Kedge P&L, Burn & Runway'!C17-'Kedge P&L, Burn & Runway'!D15+'Kedge P&L, Burn & Runway'!D16 -> 1641.8182 | E17: ='Kedge P&L, Burn & Runway'!D17-'Kedge P&L, Burn & Runway'!E15+'Kedge P&L, Burn & Runway'!E16 -> 2861.6364 | F17: ='Kedge P&L, Burn & Runway'!E17-'Kedge P&L, Burn & Runway'!F15+'Kedge P&L, Burn & Runway'!F16 -> 4417.7273 | G17: ='Kedge P&L, Burn & Runway'!F17-'Kedge P&L, Burn & Runway'!G15+'Kedge P&L, Burn & Runway'!G16 -> 6310.0909 | H17: ='Kedge P&L, Burn & Runway'!G17-'Kedge P&L, Burn & Runway'!H15+'Kedge P&L, Burn & Runway'!H16 -> 60538.727 | I17: ='Kedge P&L, Burn & Runway'!H17-'Kedge P&L, Burn & Runway'!I15+'Kedge P&L, Burn & Runway'!I16 -> 55103.636 | J17: ='Kedge P&L, Burn & Runway'!I17-'Kedge P&L, Burn & Runway'!J15+'Kedge P&L, Burn & Runway'!J16 -> 50004.818 | ... Y17: ='Kedge P&L, Burn & Runway'!X17-'Kedge P&L, Burn & Runway'!Y15+'Kedge P&L, Burn & Runway'!Y16 -> -12354
A18: Funding needed to date | B18: =IF(IF(IF(ISERROR(-'Kedge P&L, Burn & Runway'!B17>'Model inputs'!B14),-'Kedge P&L, Burn & Runway'!B17>'Model inputs'!B14,IF('Model inputs'!B14="","",-'Kedge P&L, Burn & Runway'!B17>'Model inputs'!B14))="",FALSE,IF(ISERROR(-'Kedge P&L, Burn & Runway'!B17>'Model inputs'!B14),-'Kedge P&L, Burn & Runway'!B17>'Model inputs'!B14,IF('Model inputs'!B14="","",-'Kedge P&L, Burn & Runway'!B17>'Model inputs'!B14))),-'Kedge P&L, Burn & Runway'!B17,IF('Model inputs'!B14="","",'Model inputs'!B14)) -> 0 | C18: =IF(IF(IF(ISERROR(-'Kedge P&L, Burn & Runway'!C17>'Kedge P&L, Burn & Runway'!B18),-'Kedge P&L, Burn & Runway'!C17>'Kedge P&L, Burn & Runway'!B18,IF('Kedge P&L, Burn & Runway'!B18="","",-'Kedge P&L, Burn & Runway'!C17>'Kedge P&L, Burn & Runway'!B18))="",FALSE,IF(ISERROR(-'Kedge P&L, Burn & Runway'!C17>'Kedge P&L, Burn & Runway'!B18),-'Kedge P&L, Burn & Runway'!C17>'Kedge P&L, Burn & Runway'!B18,IF('Kedge P&L, Burn & Runway'!B18="","",-'Kedge P&L, Burn & Runway'!C17>'Kedge P&L, Burn & Runway'!B18))),-'Kedge P&L, Burn & Runway'!C17,IF('Kedge P&L, Burn & Runway'!B18="","",'Kedge P&L, Burn & Runway'!B18)) -> 0 | D18: =IF(IF(IF(ISERROR(-'Kedge P&L, Burn & Runway'!D17>'Kedge P&L, Burn & Runway'!C18),-'Kedge P&L, Burn & Runway'!D17>'Kedge P&L, Burn & Runway'!C18,IF('Kedge P&L, Burn & Runway'!C18="","",-'Kedge P&L, Burn & Runway'!D17>'Kedge P&L, Burn & Runway'!C18))="",FALSE,IF(ISERROR(-'Kedge P&L, Burn & Runway'!D17>'Kedge P&L, Burn & Runway'!C18),-'Kedge P&L, Burn & Runway'!D17>'Kedge P&L, Burn & Runway'!C18,IF('Kedge P&L, Burn & Runway'!C18="","",-'Kedge P&L, Burn & Runway'!D17>'Kedge P&L, Burn & Runway'!C18))),-'Kedge P&L, Burn & Runway'!D17,IF('Kedge P&L, Burn & Runway'!C18="","",'Kedge P&L, Burn & Runway'!C18)) -> 0 | E18: =IF(IF(IF(ISERROR(-'Kedge P&L, Burn & Runway'!E17>'Kedge P&L, Burn & Runway'!D18),-'Kedge P&L, Burn & Runway'!E17>'Kedge P&L, Burn & Runway'!D18,IF('Kedge P&L, Burn & Runway'!D18="","",-'Kedge P&L, Burn & Runway'!E17>'Kedge P&L, Burn & Runway'!D18))="",FALSE,IF(ISERROR(-'Kedge P&L, Burn & Runway'!E17>'Kedge P&L, Burn & Runway'!D18),-'Kedge P&L, Burn & Runway'!E17>'Kedge P&L, Burn & Runway'!D18,IF('Kedge P&L, Burn & Runway'!D18="","",-'Kedge P&L, Burn & Runway'!E17>'Kedge P&L, Burn & Runway'!D18))),-'Kedge P&L, Burn & Runway'!E17,IF('Kedge P&L, Burn & Runway'!D18="","",'Kedge P&L, Burn & Runway'!D18)) -> 0 | F18: =IF(IF(IF(ISERROR(-'Kedge P&L, Burn & Runway'!F17>'Kedge P&L, Burn & Runway'!E18),-'Kedge P&L, Burn & Runway'!F17>'Kedge P&L, Burn & Runway'!E18,IF('Kedge P&L, Burn & Runway'!E18="","",-'Kedge P&L, Burn & Runway'!F17>'Kedge P&L, Burn & Runway'!E18))="",FALSE,IF(ISERROR(-'Kedge P&L, Burn & Runway'!F17>'Kedge P&L, Burn & Runway'!E18),-'Kedge P&L, Burn & Runway'!F17>'Kedge P&L, Burn & Runway'!E18,IF('Kedge P&L, Burn & Runway'!E18="","",-'Kedge P&L, Burn & Runway'!F17>'Kedge P&L, Burn & Runway'!E18))),-'Kedge P&L, Burn & Runway'!F17,IF('Kedge P&L, Burn & Runway'!E18="","",'Kedge P&L, Burn & Runway'!E18)) -> 0 | G18: =IF(IF(IF(ISERROR(-'Kedge P&L, Burn & Runway'!G17>'Kedge P&L, Burn & Runway'!F18),-'Kedge P&L, Burn & Runway'!G17>'Kedge P&L, Burn & Runway'!F18,IF('Kedge P&L, Burn & Runway'!F18="","",-'Kedge P&L, Burn & Runway'!G17>'Kedge P&L, Burn & Runway'!F18))="",FALSE,IF(ISERROR(-'Kedge P&L, Burn & Runway'!G17>'Kedge P&L, Burn & Runway'!F18),-'Kedge P&L, Burn & Runway'!G17>'Kedge P&L, Burn & Runway'!F18,IF('Kedge P&L, Burn & Runway'!F18="","",-'Kedge P&L, Burn & Runway'!G17>'Kedge P&L, Burn & Runway'!F18))),-'Kedge P&L, Burn & Runway'!G17,IF('Kedge P&L, Burn & Runway'!F18="","",'Kedge P&L, Burn & Runway'!F18)) -> 0 | H18: =IF(IF(IF(ISERROR(-'Kedge P&L, Burn & Runway'!H17>'Kedge P&L, Burn & Runway'!G18),-'Kedge P&L, Burn & Runway'!H17>'Kedge P&L, Burn & Runway'!G18,IF('Kedge P&L, Burn & Runway'!G18="","",-'Kedge P&L, Burn & Runway'!H17>'Kedge P&L, Burn & Runway'!G18))="",FALSE,IF(ISERROR(-'Kedge P&L, Burn & Runway'!H17>'Kedge P&L, Burn & Runway'!G18),-'Kedge P&L, Burn & Runway'!H17>'Kedge P&L, Burn & Runway'!G18,IF('Kedge P&L, Burn & Runway'!G18="","",-'Kedge P&L, Burn & Runway'!H17>'Kedge P&L, Burn & Runway'!G18))),-'Kedge P&L, Burn & Runway'!H17,IF('Kedge P&L, Burn & Runway'!G18="","",'Kedge P&L, Burn & Runway'!G18)) -> 0 | I18: =IF(IF(IF(ISERROR(-'Kedge P&L, Burn & Runway'!I17>'Kedge P&L, Burn & Runway'!H18),-'Kedge P&L, Burn & Runway'!I17>'Kedge P&L, Burn & Runway'!H18,IF('Kedge P&L, Burn & Runway'!H18="","",-'Kedge P&L, Burn & Runway'!I17>'Kedge P&L, Burn & Runway'!H18))="",FALSE,IF(ISERROR(-'Kedge P&L, Burn & Runway'!I17>'Kedge P&L, Burn & Runway'!H18),-'Kedge P&L, Burn & Runway'!I17>'Kedge P&L, Burn & Runway'!H18,IF('Kedge P&L, Burn & Runway'!H18="","",-'Kedge P&L, Burn & Runway'!I17>'Kedge P&L, Burn & Runway'!H18))),-'Kedge P&L, Burn & Runway'!I17,IF('Kedge P&L, Burn & Runway'!H18="","",'Kedge P&L, Burn & Runway'!H18)) -> 0 | J18: =IF(IF(IF(ISERROR(-'Kedge P&L, Burn & Runway'!J17>'Kedge P&L, Burn & Runway'!I18),-'Kedge P&L, Burn & Runway'!J17>'Kedge P&L, Burn & Runway'!I18,IF('Kedge P&L, Burn & Runway'!I18="","",-'Kedge P&L, Burn & Runway'!J17>'Kedge P&L, Burn & Runway'!I18))="",FALSE,IF(ISERROR(-'Kedge P&L, Burn & Runway'!J17>'Kedge P&L, Burn & Runway'!I18),-'Kedge P&L, Burn & Runway'!J17>'Kedge P&L, Burn & Runway'!I18,IF('Kedge P&L, Burn & Runway'!I18="","",-'Kedge P&L, Burn & Runway'!J17>'Kedge P&L, Burn & Runway'!I18))),-'Kedge P&L, Burn & Runway'!J17,IF('Kedge P&L, Burn & Runway'!I18="","",'Kedge P&L, Burn & Runway'!I18)) -> 0 | ... Y18: =IF(IF(IF(ISERROR(-'Kedge P&L, Burn & Runway'!Y17>'Kedge P&L, Burn & Runway'!X18),-'Kedge P&L, Burn & Runway'!Y17>'Kedge P&L, Burn & Runway'!X18,IF('Kedge P&L, Burn & Runway'!X18="","",-'Kedge P&L, Burn & Runway'!Y17>'Kedge P&L, Burn & Runway'!X18))="",FALSE,IF(ISERROR(-'Kedge P&L, Burn & Runway'!Y17>'Kedge P&L, Burn & Runway'!X18),-'Kedge P&L, Burn & Runway'!Y17>'Kedge P&L, Burn & Runway'!X18,IF('Kedge P&L, Burn & Runway'!X18="","",-'Kedge P&L, Burn & Runway'!Y17>'Kedge P&L, Burn & Runway'!X18))),-'Kedge P&L, Burn & Runway'!Y17,IF('Kedge P&L, Burn & Runway'!X18="","",'Kedge P&L, Burn & Runway'!X18)) -> 12354
A19: Runway (months) | B19: =IF(IF(IF(ISERROR('Kedge P&L, Burn & Runway'!B15>0),'Kedge P&L, Burn & Runway'!B15>0,IF('Kedge P&L, Burn & Runway'!B15="","",'Kedge P&L, Burn & Runway'!B15>0))="",FALSE,IF(ISERROR('Kedge P&L, Burn & Runway'!B15>0),'Kedge P&L, Burn & Runway'!B15>0,IF('Kedge P&L, Burn & Runway'!B15="","",'Kedge P&L, Burn & Runway'!B15>0))),IF(IF(IF(ISERROR('Kedge P&L, Burn & Runway'!B17>0),'Kedge P&L, Burn & Runway'!B17>0,IF('Kedge P&L, Burn & Runway'!B17="","",'Kedge P&L, Burn & Runway'!B17>0))="",FALSE,IF(ISERROR('Kedge P&L, Burn & Runway'!B17>0),'Kedge P&L, Burn & Runway'!B17>0,IF('Kedge P&L, Burn & Runway'!B17="","",'Kedge P&L, Burn & Runway'!B17>0))),'Kedge P&L, Burn & Runway'!B17/'Kedge P&L, Burn & Runway'!B15,0),"") | C19: =IF(IF(IF(ISERROR('Kedge P&L, Burn & Runway'!C15>0),'Kedge P&L, Burn & Runway'!C15>0,IF('Kedge P&L, Burn & Runway'!C15="","",'Kedge P&L, Burn & Runway'!C15>0))="",FALSE,IF(ISERROR('Kedge P&L, Burn & Runway'!C15>0),'Kedge P&L, Burn & Runway'!C15>0,IF('Kedge P&L, Burn & Runway'!C15="","",'Kedge P&L, Burn & Runway'!C15>0))),IF(IF(IF(ISERROR('Kedge P&L, Burn & Runway'!C17>0),'Kedge P&L, Burn & Runway'!C17>0,IF('Kedge P&L, Burn & Runway'!C17="","",'Kedge P&L, Burn & Runway'!C17>0))="",FALSE,IF(ISERROR('Kedge P&L, Burn & Runway'!C17>0),'Kedge P&L, Burn & Runway'!C17>0,IF('Kedge P&L, Burn & Runway'!C17="","",'Kedge P&L, Burn & Runway'!C17>0))),'Kedge P&L, Burn & Runway'!C17/'Kedge P&L, Burn & Runway'!C15,0),"") | D19: =IF(IF(IF(ISERROR('Kedge P&L, Burn & Runway'!D15>0),'Kedge P&L, Burn & Runway'!D15>0,IF('Kedge P&L, Burn & Runway'!D15="","",'Kedge P&L, Burn & Runway'!D15>0))="",FALSE,IF(ISERROR('Kedge P&L, Burn & Runway'!D15>0),'Kedge P&L, Burn & Runway'!D15>0,IF('Kedge P&L, Burn & Runway'!D15="","",'Kedge P&L, Burn & Runway'!D15>0))),IF(IF(IF(ISERROR('Kedge P&L, Burn & Runway'!D17>0),'Kedge P&L, Burn & Runway'!D17>0,IF('Kedge P&L, Burn & Runway'!D17="","",'Kedge P&L, Burn & Runway'!D17>0))="",FALSE,IF(ISERROR('Kedge P&L, Burn & Runway'!D17>0),'Kedge P&L, Burn & Runway'!D17>0,IF('Kedge P&L, Burn & Runway'!D17="","",'Kedge P&L, Burn & Runway'!D17>0))),'Kedge P&L, Burn & Runway'!D17/'Kedge P&L, Burn & Runway'!D15,0),"") | E19: =IF(IF(IF(ISERROR('Kedge P&L, Burn & Runway'!E15>0),'Kedge P&L, Burn & Runway'!E15>0,IF('Kedge P&L, Burn & Runway'!E15="","",'Kedge P&L, Burn & Runway'!E15>0))="",FALSE,IF(ISERROR('Kedge P&L, Burn & Runway'!E15>0),'Kedge P&L, Burn & Runway'!E15>0,IF('Kedge P&L, Burn & Runway'!E15="","",'Kedge P&L, Burn & Runway'!E15>0))),IF(IF(IF(ISERROR('Kedge P&L, Burn & Runway'!E17>0),'Kedge P&L, Burn & Runway'!E17>0,IF('Kedge P&L, Burn & Runway'!E17="","",'Kedge P&L, Burn & Runway'!E17>0))="",FALSE,IF(ISERROR('Kedge P&L, Burn & Runway'!E17>0),'Kedge P&L, Burn & Runway'!E17>0,IF('Kedge P&L, Burn & Runway'!E17="","",'Kedge P&L, Burn & Runway'!E17>0))),'Kedge P&L, Burn & Runway'!E17/'Kedge P&L, Burn & Runway'!E15,0),"") | F19: =IF(IF(IF(ISERROR('Kedge P&L, Burn & Runway'!F15>0),'Kedge P&L, Burn & Runway'!F15>0,IF('Kedge P&L, Burn & Runway'!F15="","",'Kedge P&L, Burn & Runway'!F15>0))="",FALSE,IF(ISERROR('Kedge P&L, Burn & Runway'!F15>0),'Kedge P&L, Burn & Runway'!F15>0,IF('Kedge P&L, Burn & Runway'!F15="","",'Kedge P&L, Burn & Runway'!F15>0))),IF(IF(IF(ISERROR('Kedge P&L, Burn & Runway'!F17>0),'Kedge P&L, Burn & Runway'!F17>0,IF('Kedge P&L, Burn & Runway'!F17="","",'Kedge P&L, Burn & Runway'!F17>0))="",FALSE,IF(ISERROR('Kedge P&L, Burn & Runway'!F17>0),'Kedge P&L, Burn & Runway'!F17>0,IF('Kedge P&L, Burn & Runway'!F17="","",'Kedge P&L, Burn & Runway'!F17>0))),'Kedge P&L, Burn & Runway'!F17/'Kedge P&L, Burn & Runway'!F15,0),"") | G19: =IF(IF(IF(ISERROR('Kedge P&L, Burn & Runway'!G15>0),'Kedge P&L, Burn & Runway'!G15>0,IF('Kedge P&L, Burn & Runway'!G15="","",'Kedge P&L, Burn & Runway'!G15>0))="",FALSE,IF(ISERROR('Kedge P&L, Burn & Runway'!G15>0),'Kedge P&L, Burn & Runway'!G15>0,IF('Kedge P&L, Burn & Runway'!G15="","",'Kedge P&L, Burn & Runway'!G15>0))),IF(IF(IF(ISERROR('Kedge P&L, Burn & Runway'!G17>0),'Kedge P&L, Burn & Runway'!G17>0,IF('Kedge P&L, Burn & Runway'!G17="","",'Kedge P&L, Burn & Runway'!G17>0))="",FALSE,IF(ISERROR('Kedge P&L, Burn & Runway'!G17>0),'Kedge P&L, Burn & Runway'!G17>0,IF('Kedge P&L, Burn & Runway'!G17="","",'Kedge P&L, Burn & Runway'!G17>0))),'Kedge P&L, Burn & Runway'!G17/'Kedge P&L, Burn & Runway'!G15,0),"") | H19: =IF(IF(IF(ISERROR('Kedge P&L, Burn & Runway'!H15>0),'Kedge P&L, Burn & Runway'!H15>0,IF('Kedge P&L, Burn & Runway'!H15="","",'Kedge P&L, Burn & Runway'!H15>0))="",FALSE,IF(ISERROR('Kedge P&L, Burn & Runway'!H15>0),'Kedge P&L, Burn & Runway'!H15>0,IF('Kedge P&L, Burn & Runway'!H15="","",'Kedge P&L, Burn & Runway'!H15>0))),IF(IF(IF(ISERROR('Kedge P&L, Burn & Runway'!H17>0),'Kedge P&L, Burn & Runway'!H17>0,IF('Kedge P&L, Burn & Runway'!H17="","",'Kedge P&L, Burn & Runway'!H17>0))="",FALSE,IF(ISERROR('Kedge P&L, Burn & Runway'!H17>0),'Kedge P&L, Burn & Runway'!H17>0,IF('Kedge P&L, Burn & Runway'!H17="","",'Kedge P&L, Burn & Runway'!H17>0))),'Kedge P&L, Burn & Runway'!H17/'Kedge P&L, Burn & Runway'!H15,0),"") -> 10.489501 | I19: =IF(IF(IF(ISERROR('Kedge P&L, Burn & Runway'!I15>0),'Kedge P&L, Burn & Runway'!I15>0,IF('Kedge P&L, Burn & Runway'!I15="","",'Kedge P&L, Burn & Runway'!I15>0))="",FALSE,IF(ISERROR('Kedge P&L, Burn & Runway'!I15>0),'Kedge P&L, Burn & Runway'!I15>0,IF('Kedge P&L, Burn & Runway'!I15="","",'Kedge P&L, Burn & Runway'!I15>0))),IF(IF(IF(ISERROR('Kedge P&L, Burn & Runway'!I17>0),'Kedge P&L, Burn & Runway'!I17>0,IF('Kedge P&L, Burn & Runway'!I17="","",'Kedge P&L, Burn & Runway'!I17>0))="",FALSE,IF(ISERROR('Kedge P&L, Burn & Runway'!I17>0),'Kedge P&L, Burn & Runway'!I17>0,IF('Kedge P&L, Burn & Runway'!I17="","",'Kedge P&L, Burn & Runway'!I17>0))),'Kedge P&L, Burn & Runway'!I17/'Kedge P&L, Burn & Runway'!I15,0),"") -> 10.138494 | ... Y19: =IF(IF(IF(ISERROR('Kedge P&L, Burn & Runway'!Y15>0),'Kedge P&L, Burn & Runway'!Y15>0,IF('Kedge P&L, Burn & Runway'!Y15="","",'Kedge P&L, Burn & Runway'!Y15>0))="",FALSE,IF(ISERROR('Kedge P&L, Burn & Runway'!Y15>0),'Kedge P&L, Burn & Runway'!Y15>0,IF('Kedge P&L, Burn & Runway'!Y15="","",'Kedge P&L, Burn & Runway'!Y15>0))),IF(IF(IF(ISERROR('Kedge P&L, Burn & Runway'!Y17>0),'Kedge P&L, Burn & Runway'!Y17>0,IF('Kedge P&L, Burn & Runway'!Y17="","",'Kedge P&L, Burn & Runway'!Y17>0))="",FALSE,IF(ISERROR('Kedge P&L, Burn & Runway'!Y17>0),'Kedge P&L, Burn & Runway'!Y17>0,IF('Kedge P&L, Burn & Runway'!Y17="","",'Kedge P&L, Burn & Runway'!Y17>0))),'Kedge P&L, Burn & Runway'!Y17/'Kedge P&L, Burn & Runway'!Y15,0),"") -> 0

Sheet Stress Unit Economics & Funding
A1: Stress Unit Economics & Funding
A2: Operating Model · Stress: Sonnet on big repos
A4: Variable / dimension | B4: 2026-10 | C4: 2026-11 | D4: 2026-12 | E4: 2027-01 | F4: 2027-02 | G4: 2027-03 | H4: 2027-04 | I4: 2027-05 | J4: 2027-06 | K4: 2027-07 | L4: 2027-08 | M4: 2027-09 | N4: 2027-10 | O4: 2027-11 | P4: 2027-12 | Q4: 2028-01 | R4: 2028-02 | S4: 2028-03 | T4: 2028-04 | U4: 2028-05 | V4: 2028-06 | W4: 2028-07 | X4: 2028-08 | Y4: 2028-09
A5: Contribution per active team | B5: ='Model inputs'!AA26*'Model inputs'!AA15*('Model inputs'!AA25*(1-'Model inputs'!AA24)-'Model inputs'!AA18) -> 82.2 | C5: ='Model inputs'!AA26*'Model inputs'!AA15*('Model inputs'!AA25*(1-'Model inputs'!AA24)-'Model inputs'!AA18) -> 82.2 | D5: ='Model inputs'!AA26*'Model inputs'!AA15*('Model inputs'!AA25*(1-'Model inputs'!AA24)-'Model inputs'!AA18) -> 82.2 | E5: ='Model inputs'!AA26*'Model inputs'!AA15*('Model inputs'!AA25*(1-'Model inputs'!AA24)-'Model inputs'!AA18) -> 82.2 | F5: ='Model inputs'!AA26*'Model inputs'!AA15*('Model inputs'!AA25*(1-'Model inputs'!AA24)-'Model inputs'!AA18) -> 82.2 | G5: ='Model inputs'!AA26*'Model inputs'!AA15*('Model inputs'!AA25*(1-'Model inputs'!AA24)-'Model inputs'!AA18) -> 82.2 | H5: ='Model inputs'!AA26*'Model inputs'!AA15*('Model inputs'!AA25*(1-'Model inputs'!AA24)-'Model inputs'!AA18) -> 82.2 | I5: ='Model inputs'!AA26*'Model inputs'!AA15*('Model inputs'!AA25*(1-'Model inputs'!AA24)-'Model inputs'!AA18) -> 82.2 | J5: ='Model inputs'!AA26*'Model inputs'!AA15*('Model inputs'!AA25*(1-'Model inputs'!AA24)-'Model inputs'!AA18) -> 82.2 | K5: ='Model inputs'!AA26*'Model inputs'!AA15*('Model inputs'!AA25*(1-'Model inputs'!AA24)-'Model inputs'!AA18) -> 82.2 | L5: ='Model inputs'!AA26*'Model inputs'!AA15*('Model inputs'!AA25*(1-'Model inputs'!AA24)-'Model inputs'!AA18) -> 82.2 | M5: ='Model inputs'!AA26*'Model inputs'!AA15*('Model inputs'!AA25*(1-'Model inputs'!AA24)-'Model inputs'!AA18) -> 82.2 | N5: ='Model inputs'!AA26*'Model inputs'!AA15*('Model inputs'!AA25*(1-'Model inputs'!AA24)-'Model inputs'!AA18) -> 82.2 | O5: ='Model inputs'!AA26*'Model inputs'!AA15*('Model inputs'!AA25*(1-'Model inputs'!AA24)-'Model inputs'!AA18) -> 82.2 | P5: ='Model inputs'!AA26*'Model inputs'!AA15*('Model inputs'!AA25*(1-'Model inputs'!AA24)-'Model inputs'!AA18) -> 82.2 | Q5: ='Model inputs'!AA26*'Model inputs'!AA15*('Model inputs'!AA25*(1-'Model inputs'!AA24)-'Model inputs'!AA18) -> 82.2 | R5: ='Model inputs'!AA26*'Model inputs'!AA15*('Model inputs'!AA25*(1-'Model inputs'!AA24)-'Model inputs'!AA18) -> 82.2 | S5: ='Model inputs'!AA26*'Model inputs'!AA15*('Model inputs'!AA25*(1-'Model inputs'!AA24)-'Model inputs'!AA18) -> 82.2 | T5: ='Model inputs'!AA26*'Model inputs'!AA15*('Model inputs'!AA25*(1-'Model inputs'!AA24)-'Model inputs'!AA18) -> 82.2 | U5: ='Model inputs'!AA26*'Model inputs'!AA15*('Model inputs'!AA25*(1-'Model inputs'!AA24)-'Model inputs'!AA18) -> 82.2 | V5: ='Model inputs'!AA26*'Model inputs'!AA15*('Model inputs'!AA25*(1-'Model inputs'!AA24)-'Model inputs'!AA18) -> 82.2 | W5: ='Model inputs'!AA26*'Model inputs'!AA15*('Model inputs'!AA25*(1-'Model inputs'!AA24)-'Model inputs'!AA18) -> 82.2 | X5: ='Model inputs'!AA26*'Model inputs'!AA15*('Model inputs'!AA25*(1-'Model inputs'!AA24)-'Model inputs'!AA18) -> 82.2 | Y5: ='Model inputs'!AA26*'Model inputs'!AA15*('Model inputs'!AA25*(1-'Model inputs'!AA24)-'Model inputs'!AA18) -> 82.2
A6: Active teams for paid-founder break-even | B6: =CEILING(('Model inputs'!AA13*'Model inputs'!AA11+'Model inputs'!AA29)/'Stress Unit Economics & Funding'!B5,1) -> 100 | C6: =CEILING(('Model inputs'!AA13*'Model inputs'!AA11+'Model inputs'!AA29)/'Stress Unit Economics & Funding'!C5,1) -> 100 | D6: =CEILING(('Model inputs'!AA13*'Model inputs'!AA11+'Model inputs'!AA29)/'Stress Unit Economics & Funding'!D5,1) -> 100 | E6: =CEILING(('Model inputs'!AA13*'Model inputs'!AA11+'Model inputs'!AA29)/'Stress Unit Economics & Funding'!E5,1) -> 100 | F6: =CEILING(('Model inputs'!AA13*'Model inputs'!AA11+'Model inputs'!AA29)/'Stress Unit Economics & Funding'!F5,1) -> 100 | G6: =CEILING(('Model inputs'!AA13*'Model inputs'!AA11+'Model inputs'!AA29)/'Stress Unit Economics & Funding'!G5,1) -> 100 | H6: =CEILING(('Model inputs'!AA13*'Model inputs'!AA11+'Model inputs'!AA29)/'Stress Unit Economics & Funding'!H5,1) -> 100 | I6: =CEILING(('Model inputs'!AA13*'Model inputs'!AA11+'Model inputs'!AA29)/'Stress Unit Economics & Funding'!I5,1) -> 100 | J6: =CEILING(('Model inputs'!AA13*'Model inputs'!AA11+'Model inputs'!AA29)/'Stress Unit Economics & Funding'!J5,1) -> 100 | K6: =CEILING(('Model inputs'!AA13*'Model inputs'!AA11+'Model inputs'!AA29)/'Stress Unit Economics & Funding'!K5,1) -> 100 | L6: =CEILING(('Model inputs'!AA13*'Model inputs'!AA11+'Model inputs'!AA29)/'Stress Unit Economics & Funding'!L5,1) -> 100 | M6: =CEILING(('Model inputs'!AA13*'Model inputs'!AA11+'Model inputs'!AA29)/'Stress Unit Economics & Funding'!M5,1) -> 100 | N6: =CEILING(('Model inputs'!AA13*'Model inputs'!AA11+'Model inputs'!AA29)/'Stress Unit Economics & Funding'!N5,1) -> 100 | O6: =CEILING(('Model inputs'!AA13*'Model inputs'!AA11+'Model inputs'!AA29)/'Stress Unit Economics & Funding'!O5,1) -> 100 | P6: =CEILING(('Model inputs'!AA13*'Model inputs'!AA11+'Model inputs'!AA29)/'Stress Unit Economics & Funding'!P5,1) -> 100 | Q6: =CEILING(('Model inputs'!AA13*'Model inputs'!AA11+'Model inputs'!AA29)/'Stress Unit Economics & Funding'!Q5,1) -> 100 | R6: =CEILING(('Model inputs'!AA13*'Model inputs'!AA11+'Model inputs'!AA29)/'Stress Unit Economics & Funding'!R5,1) -> 100 | S6: =CEILING(('Model inputs'!AA13*'Model inputs'!AA11+'Model inputs'!AA29)/'Stress Unit Economics & Funding'!S5,1) -> 100 | T6: =CEILING(('Model inputs'!AA13*'Model inputs'!AA11+'Model inputs'!AA29)/'Stress Unit Economics & Funding'!T5,1) -> 100 | U6: =CEILING(('Model inputs'!AA13*'Model inputs'!AA11+'Model inputs'!AA29)/'Stress Unit Economics & Funding'!U5,1) -> 100 | V6: =CEILING(('Model inputs'!AA13*'Model inputs'!AA11+'Model inputs'!AA29)/'Stress Unit Economics & Funding'!V5,1) -> 100 | W6: =CEILING(('Model inputs'!AA13*'Model inputs'!AA11+'Model inputs'!AA29)/'Stress Unit Economics & Funding'!W5,1) -> 100 | X6: =CEILING(('Model inputs'!AA13*'Model inputs'!AA11+'Model inputs'!AA29)/'Stress Unit Economics & Funding'!X5,1) -> 100 | Y6: =CEILING(('Model inputs'!AA13*'Model inputs'!AA11+'Model inputs'!AA29)/'Stress Unit Economics & Funding'!Y5,1) -> 100
A7: Cash excluding raises | B7: ='Model inputs'!B8-'Kedge P&L, Burn & Runway'!B15 -> 211 | C7: ='Stress Unit Economics & Funding'!B7-'Kedge P&L, Burn & Runway'!C15 -> 758.27273 | D7: ='Stress Unit Economics & Funding'!C7-'Kedge P&L, Burn & Runway'!D15 -> 1641.8182 | E7: ='Stress Unit Economics & Funding'!D7-'Kedge P&L, Burn & Runway'!E15 -> 2861.6364 | F7: ='Stress Unit Economics & Funding'!E7-'Kedge P&L, Burn & Runway'!F15 -> 4417.7273 | G7: ='Stress Unit Economics & Funding'!F7-'Kedge P&L, Burn & Runway'!G15 -> 6310.0909 | H7: ='Stress Unit Economics & Funding'!G7-'Kedge P&L, Burn & Runway'!H15 -> 538.72727 | I7: ='Stress Unit Economics & Funding'!H7-'Kedge P&L, Burn & Runway'!I15 -> -4896.3636 | J7: ='Stress Unit Economics & Funding'!I7-'Kedge P&L, Burn & Runway'!J15 -> -9995.1818 | ... Y7: ='Stress Unit Economics & Funding'!X7-'Kedge P&L, Burn & Runway'!Y15 -> -72354
A8: Total minimum funding needed | B8: =MAX(0,-'Stress Unit Economics & Funding'!B7,'Model inputs'!B30) -> 0 | C8: =MAX(0,-'Stress Unit Economics & Funding'!C7,'Stress Unit Economics & Funding'!B8) -> 0 | D8: =MAX(0,-'Stress Unit Economics & Funding'!D7,'Stress Unit Economics & Funding'!C8) -> 0 | E8: =MAX(0,-'Stress Unit Economics & Funding'!E7,'Stress Unit Economics & Funding'!D8) -> 0 | F8: =MAX(0,-'Stress Unit Economics & Funding'!F7,'Stress Unit Economics & Funding'!E8) -> 0 | G8: =MAX(0,-'Stress Unit Economics & Funding'!G7,'Stress Unit Economics & Funding'!F8) -> 0 | H8: =MAX(0,-'Stress Unit Economics & Funding'!H7,'Stress Unit Economics & Funding'!G8) -> 0 | I8: =MAX(0,-'Stress Unit Economics & Funding'!I7,'Stress Unit Economics & Funding'!H8) -> 4896.3636 | J8: =MAX(0,-'Stress Unit Economics & Funding'!J7,'Stress Unit Economics & Funding'!I8) -> 9995.1818 | ... Y8: =MAX(0,-'Stress Unit Economics & Funding'!Y7,'Stress Unit Economics & Funding'!X8) -> 72354

Sheet Model inputs
A1: Model inputs
A2: Integration values are aggregated snapshots; raw source records are not included.
A4: Variables
A5: Variable / segment | B5: 2026-09 | C5: 2026-10 | D5: 2026-11 | E5: 2026-12 | F5: 2027-01 | G5: 2027-02 | H5: 2027-03 | I5: 2027-04 | J5: 2027-05 | K5: 2027-06 | L5: 2027-07 | M5: 2027-08 | N5: 2027-09 | O5: 2027-10 | P5: 2027-11 | Q5: 2027-12 | R5: 2028-01 | S5: 2028-02 | T5: 2028-03 | U5: 2028-04 | V5: 2028-05 | W5: 2028-06 | X5: 2028-07 | Y5: 2028-08 | Z5: 2028-09 | AA5: Value | AB5: 2026-01 | AC5: 2026-02 | AD5: 2026-03 | AE5: 2026-04 | AF5: 2026-05 | AG5: 2026-06 | AH5: 2026-07 | AI5: 2026-08
A6: AI model costs | B6: 0 | C6: ='Model inputs'!C16*'Model inputs'!AA18 -> 171 | D6: ='Model inputs'!D16*'Model inputs'!AA18 -> 310.90909 | E6: ='Model inputs'!E16*'Model inputs'!AA18 -> 450.81818 | F6: ='Model inputs'!F16*'Model inputs'!AA18 -> 590.72727 | G6: ='Model inputs'!G16*'Model inputs'!AA18 -> 730.63636 | H6: ='Model inputs'!H16*'Model inputs'!AA18 -> 870.54545 | I6: ='Model inputs'!I16*'Model inputs'!AA18 -> 1010.4545 | J6: ='Model inputs'!J16*'Model inputs'!AA18 -> 1150.3636 | K6: ='Model inputs'!K16*'Model inputs'!AA18 -> 1290.2727 | L6: ='Model inputs'!L16*'Model inputs'!AA18 -> 1430.1818 | M6: ='Model inputs'!M16*'Model inputs'!AA18 -> 1570.0909 | N6: ='Model inputs'!N16*'Model inputs'!AA18 -> 1710 | O6: ='Model inputs'!O16*'Model inputs'!AA18 -> 1710 | P6: ='Model inputs'!P16*'Model inputs'!AA18 -> 1710 | Q6: ='Model inputs'!Q16*'Model inputs'!AA18 -> 1710 | R6: ='Model inputs'!R16*'Model inputs'!AA18 -> 1710 | S6: ='Model inputs'!S16*'Model inputs'!AA18 -> 1710 | T6: ='Model inputs'!T16*'Model inputs'!AA18 -> 1710 | U6: ='Model inputs'!U16*'Model inputs'!AA18 -> 1710 | V6: ='Model inputs'!V16*'Model inputs'!AA18 -> 1710 | W6: ='Model inputs'!W16*'Model inputs'!AA18 -> 1710 | X6: ='Model inputs'!X16*'Model inputs'!AA18 -> 1710 | Y6: ='Model inputs'!Y16*'Model inputs'!AA18 -> 1710 | Z6: ='Model inputs'!Z16*'Model inputs'!AA18 -> 1710
A7: Cash balance | B7: =IF('Model inputs'!AA34="","",'Model inputs'!AA34) -> 0 | C7: ='Model inputs'!B7-'Model inputs'!C20+'Model inputs'!C10 -> 211 | D7: ='Model inputs'!C7-'Model inputs'!D20+'Model inputs'!D10 -> 758.27273 | E7: ='Model inputs'!D7-'Model inputs'!E20+'Model inputs'!E10 -> 1641.8182 | F7: ='Model inputs'!E7-'Model inputs'!F20+'Model inputs'!F10 -> 2861.6364 | G7: ='Model inputs'!F7-'Model inputs'!G20+'Model inputs'!G10 -> 4417.7273 | H7: ='Model inputs'!G7-'Model inputs'!H20+'Model inputs'!H10 -> 6310.0909 | I7: ='Model inputs'!H7-'Model inputs'!I20+'Model inputs'!I10 -> 60538.727 | J7: ='Model inputs'!I7-'Model inputs'!J20+'Model inputs'!J10 -> 55103.636 | ... Z7: ='Model inputs'!Y7-'Model inputs'!Z20+'Model inputs'!Z10 -> -12354
A8: Cash excluding raises | B8: =IF('Model inputs'!AA34="","",'Model inputs'!AA34) -> 0 | C8: ='Model inputs'!B8-'Model inputs'!C20 -> 211 | D8: ='Model inputs'!C8-'Model inputs'!D20 -> 758.27273 | E8: ='Model inputs'!D8-'Model inputs'!E20 -> 1641.8182 | F8: ='Model inputs'!E8-'Model inputs'!F20 -> 2861.6364 | G8: ='Model inputs'!F8-'Model inputs'!G20 -> 4417.7273 | H8: ='Model inputs'!G8-'Model inputs'!H20 -> 6310.0909 | I8: ='Model inputs'!H8-'Model inputs'!I20 -> 538.72727 | J8: ='Model inputs'!I8-'Model inputs'!J20 -> -4896.3636 | ... Z8: ='Model inputs'!Y8-'Model inputs'!Z20 -> -72354
A9: Cost of goods sold | B9: 0 | C9: ='Model inputs'!C6+'Model inputs'!C23 -> 189 | D9: ='Model inputs'!D6+'Model inputs'!D23 -> 343.63636 | E9: ='Model inputs'!E6+'Model inputs'!E23 -> 498.27273 | F9: ='Model inputs'!F6+'Model inputs'!F23 -> 652.90909 | G9: ='Model inputs'!G6+'Model inputs'!G23 -> 807.54545 | H9: ='Model inputs'!H6+'Model inputs'!H23 -> 962.18182 | I9: ='Model inputs'!I6+'Model inputs'!I23 -> 1116.8182 | J9: ='Model inputs'!J6+'Model inputs'!J23 -> 1271.4545 | ... Z9: ='Model inputs'!Z6+'Model inputs'!Z23 -> 1890
A10: Equity raised | B10: 0 | C10: 0 | D10: 0 | E10: 0 | F10: 0 | G10: 0 | H10: 0 | I10: =60000 -> 60000 | J10: 0 | K10: 0 | L10: 0 | M10: 0 | N10: 0 | O10: 0 | P10: 0 | Q10: 0 | R10: 0 | S10: 0 | T10: 0 | U10: 0 | V10: 0 | W10: 0 | X10: 0 | Y10: 0 | Z10: 0
A11: Founder monthly salary | AA11: =4000 -> 4000
A12: Founder salaries | B12: 0 | C12: =IF(IF(IF(ISERROR('Model inputs'!C19>'Model inputs'!AA31),'Model inputs'!C19>'Model inputs'!AA31,IF(OR('Model inputs'!C19="",'Model inputs'!AA31=""),"",'Model inputs'!C19>'Model inputs'!AA31))="",FALSE,IF(ISERROR('Model inputs'!C19>'Model inputs'!AA31),'Model inputs'!C19>'Model inputs'!AA31,IF(OR('Model inputs'!C19="",'Model inputs'!AA31=""),"",'Model inputs'!C19>'Model inputs'!AA31))),'Model inputs'!AA13*'Model inputs'!AA11,0) -> 0 | D12: =IF(IF(IF(ISERROR('Model inputs'!D19>'Model inputs'!AA31),'Model inputs'!D19>'Model inputs'!AA31,IF(OR('Model inputs'!D19="",'Model inputs'!AA31=""),"",'Model inputs'!D19>'Model inputs'!AA31))="",FALSE,IF(ISERROR('Model inputs'!D19>'Model inputs'!AA31),'Model inputs'!D19>'Model inputs'!AA31,IF(OR('Model inputs'!D19="",'Model inputs'!AA31=""),"",'Model inputs'!D19>'Model inputs'!AA31))),'Model inputs'!AA13*'Model inputs'!AA11,0) -> 0 | E12: =IF(IF(IF(ISERROR('Model inputs'!E19>'Model inputs'!AA31),'Model inputs'!E19>'Model inputs'!AA31,IF(OR('Model inputs'!E19="",'Model inputs'!AA31=""),"",'Model inputs'!E19>'Model inputs'!AA31))="",FALSE,IF(ISERROR('Model inputs'!E19>'Model inputs'!AA31),'Model inputs'!E19>'Model inputs'!AA31,IF(OR('Model inputs'!E19="",'Model inputs'!AA31=""),"",'Model inputs'!E19>'Model inputs'!AA31))),'Model inputs'!AA13*'Model inputs'!AA11,0) -> 0 | F12: =IF(IF(IF(ISERROR('Model inputs'!F19>'Model inputs'!AA31),'Model inputs'!F19>'Model inputs'!AA31,IF(OR('Model inputs'!F19="",'Model inputs'!AA31=""),"",'Model inputs'!F19>'Model inputs'!AA31))="",FALSE,IF(ISERROR('Model inputs'!F19>'Model inputs'!AA31),'Model inputs'!F19>'Model inputs'!AA31,IF(OR('Model inputs'!F19="",'Model inputs'!AA31=""),"",'Model inputs'!F19>'Model inputs'!AA31))),'Model inputs'!AA13*'Model inputs'!AA11,0) -> 0 | G12: =IF(IF(IF(ISERROR('Model inputs'!G19>'Model inputs'!AA31),'Model inputs'!G19>'Model inputs'!AA31,IF(OR('Model inputs'!G19="",'Model inputs'!AA31=""),"",'Model inputs'!G19>'Model inputs'!AA31))="",FALSE,IF(ISERROR('Model inputs'!G19>'Model inputs'!AA31),'Model inputs'!G19>'Model inputs'!AA31,IF(OR('Model inputs'!G19="",'Model inputs'!AA31=""),"",'Model inputs'!G19>'Model inputs'!AA31))),'Model inputs'!AA13*'Model inputs'!AA11,0) -> 0 | H12: =IF(IF(IF(ISERROR('Model inputs'!H19>'Model inputs'!AA31),'Model inputs'!H19>'Model inputs'!AA31,IF(OR('Model inputs'!H19="",'Model inputs'!AA31=""),"",'Model inputs'!H19>'Model inputs'!AA31))="",FALSE,IF(ISERROR('Model inputs'!H19>'Model inputs'!AA31),'Model inputs'!H19>'Model inputs'!AA31,IF(OR('Model inputs'!H19="",'Model inputs'!AA31=""),"",'Model inputs'!H19>'Model inputs'!AA31))),'Model inputs'!AA13*'Model inputs'!AA11,0) -> 0 | I12: =IF(IF(IF(ISERROR('Model inputs'!I19>'Model inputs'!AA31),'Model inputs'!I19>'Model inputs'!AA31,IF(OR('Model inputs'!I19="",'Model inputs'!AA31=""),"",'Model inputs'!I19>'Model inputs'!AA31))="",FALSE,IF(ISERROR('Model inputs'!I19>'Model inputs'!AA31),'Model inputs'!I19>'Model inputs'!AA31,IF(OR('Model inputs'!I19="",'Model inputs'!AA31=""),"",'Model inputs'!I19>'Model inputs'!AA31))),'Model inputs'!AA13*'Model inputs'!AA11,0) -> 8000 | J12: =IF(IF(IF(ISERROR('Model inputs'!J19>'Model inputs'!AA31),'Model inputs'!J19>'Model inputs'!AA31,IF(OR('Model inputs'!J19="",'Model inputs'!AA31=""),"",'Model inputs'!J19>'Model inputs'!AA31))="",FALSE,IF(ISERROR('Model inputs'!J19>'Model inputs'!AA31),'Model inputs'!J19>'Model inputs'!AA31,IF(OR('Model inputs'!J19="",'Model inputs'!AA31=""),"",'Model inputs'!J19>'Model inputs'!AA31))),'Model inputs'!AA13*'Model inputs'!AA11,0) -> 8000 | K12: =IF(IF(IF(ISERROR('Model inputs'!K19>'Model inputs'!AA31),'Model inputs'!K19>'Model inputs'!AA31,IF(OR('Model inputs'!K19="",'Model inputs'!AA31=""),"",'Model inputs'!K19>'Model inputs'!AA31))="",FALSE,IF(ISERROR('Model inputs'!K19>'Model inputs'!AA31),'Model inputs'!K19>'Model inputs'!AA31,IF(OR('Model inputs'!K19="",'Model inputs'!AA31=""),"",'Model inputs'!K19>'Model inputs'!AA31))),'Model inputs'!AA13*'Model inputs'!AA11,0) -> 8000 | L12: =IF(IF(IF(ISERROR('Model inputs'!L19>'Model inputs'!AA31),'Model inputs'!L19>'Model inputs'!AA31,IF(OR('Model inputs'!L19="",'Model inputs'!AA31=""),"",'Model inputs'!L19>'Model inputs'!AA31))="",FALSE,IF(ISERROR('Model inputs'!L19>'Model inputs'!AA31),'Model inputs'!L19>'Model inputs'!AA31,IF(OR('Model inputs'!L19="",'Model inputs'!AA31=""),"",'Model inputs'!L19>'Model inputs'!AA31))),'Model inputs'!AA13*'Model inputs'!AA11,0) -> 8000 | M12: =IF(IF(IF(ISERROR('Model inputs'!M19>'Model inputs'!AA31),'Model inputs'!M19>'Model inputs'!AA31,IF(OR('Model inputs'!M19="",'Model inputs'!AA31=""),"",'Model inputs'!M19>'Model inputs'!AA31))="",FALSE,IF(ISERROR('Model inputs'!M19>'Model inputs'!AA31),'Model inputs'!M19>'Model inputs'!AA31,IF(OR('Model inputs'!M19="",'Model inputs'!AA31=""),"",'Model inputs'!M19>'Model inputs'!AA31))),'Model inputs'!AA13*'Model inputs'!AA11,0) -> 8000 | N12: =IF(IF(IF(ISERROR('Model inputs'!N19>'Model inputs'!AA31),'Model inputs'!N19>'Model inputs'!AA31,IF(OR('Model inputs'!N19="",'Model inputs'!AA31=""),"",'Model inputs'!N19>'Model inputs'!AA31))="",FALSE,IF(ISERROR('Model inputs'!N19>'Model inputs'!AA31),'Model inputs'!N19>'Model inputs'!AA31,IF(OR('Model inputs'!N19="",'Model inputs'!AA31=""),"",'Model inputs'!N19>'Model inputs'!AA31))),'Model inputs'!AA13*'Model inputs'!AA11,0) -> 8000 | O12: =IF(IF(IF(ISERROR('Model inputs'!O19>'Model inputs'!AA31),'Model inputs'!O19>'Model inputs'!AA31,IF(OR('Model inputs'!O19="",'Model inputs'!AA31=""),"",'Model inputs'!O19>'Model inputs'!AA31))="",FALSE,IF(ISERROR('Model inputs'!O19>'Model inputs'!AA31),'Model inputs'!O19>'Model inputs'!AA31,IF(OR('Model inputs'!O19="",'Model inputs'!AA31=""),"",'Model inputs'!O19>'Model inputs'!AA31))),'Model inputs'!AA13*'Model inputs'!AA11,0) -> 8000 | P12: =IF(IF(IF(ISERROR('Model inputs'!P19>'Model inputs'!AA31),'Model inputs'!P19>'Model inputs'!AA31,IF(OR('Model inputs'!P19="",'Model inputs'!AA31=""),"",'Model inputs'!P19>'Model inputs'!AA31))="",FALSE,IF(ISERROR('Model inputs'!P19>'Model inputs'!AA31),'Model inputs'!P19>'Model inputs'!AA31,IF(OR('Model inputs'!P19="",'Model inputs'!AA31=""),"",'Model inputs'!P19>'Model inputs'!AA31))),'Model inputs'!AA13*'Model inputs'!AA11,0) -> 8000 | Q12: =IF(IF(IF(ISERROR('Model inputs'!Q19>'Model inputs'!AA31),'Model inputs'!Q19>'Model inputs'!AA31,IF(OR('Model inputs'!Q19="",'Model inputs'!AA31=""),"",'Model inputs'!Q19>'Model inputs'!AA31))="",FALSE,IF(ISERROR('Model inputs'!Q19>'Model inputs'!AA31),'Model inputs'!Q19>'Model inputs'!AA31,IF(OR('Model inputs'!Q19="",'Model inputs'!AA31=""),"",'Model inputs'!Q19>'Model inputs'!AA31))),'Model inputs'!AA13*'Model inputs'!AA11,0) -> 8000 | R12: =IF(IF(IF(ISERROR('Model inputs'!R19>'Model inputs'!AA31),'Model inputs'!R19>'Model inputs'!AA31,IF(OR('Model inputs'!R19="",'Model inputs'!AA31=""),"",'Model inputs'!R19>'Model inputs'!AA31))="",FALSE,IF(ISERROR('Model inputs'!R19>'Model inputs'!AA31),'Model inputs'!R19>'Model inputs'!AA31,IF(OR('Model inputs'!R19="",'Model inputs'!AA31=""),"",'Model inputs'!R19>'Model inputs'!AA31))),'Model inputs'!AA13*'Model inputs'!AA11,0) -> 8000 | S12: =IF(IF(IF(ISERROR('Model inputs'!S19>'Model inputs'!AA31),'Model inputs'!S19>'Model inputs'!AA31,IF(OR('Model inputs'!S19="",'Model inputs'!AA31=""),"",'Model inputs'!S19>'Model inputs'!AA31))="",FALSE,IF(ISERROR('Model inputs'!S19>'Model inputs'!AA31),'Model inputs'!S19>'Model inputs'!AA31,IF(OR('Model inputs'!S19="",'Model inputs'!AA31=""),"",'Model inputs'!S19>'Model inputs'!AA31))),'Model inputs'!AA13*'Model inputs'!AA11,0) -> 8000 | T12: =IF(IF(IF(ISERROR('Model inputs'!T19>'Model inputs'!AA31),'Model inputs'!T19>'Model inputs'!AA31,IF(OR('Model inputs'!T19="",'Model inputs'!AA31=""),"",'Model inputs'!T19>'Model inputs'!AA31))="",FALSE,IF(ISERROR('Model inputs'!T19>'Model inputs'!AA31),'Model inputs'!T19>'Model inputs'!AA31,IF(OR('Model inputs'!T19="",'Model inputs'!AA31=""),"",'Model inputs'!T19>'Model inputs'!AA31))),'Model inputs'!AA13*'Model inputs'!AA11,0) -> 8000 | U12: =IF(IF(IF(ISERROR('Model inputs'!U19>'Model inputs'!AA31),'Model inputs'!U19>'Model inputs'!AA31,IF(OR('Model inputs'!U19="",'Model inputs'!AA31=""),"",'Model inputs'!U19>'Model inputs'!AA31))="",FALSE,IF(ISERROR('Model inputs'!U19>'Model inputs'!AA31),'Model inputs'!U19>'Model inputs'!AA31,IF(OR('Model inputs'!U19="",'Model inputs'!AA31=""),"",'Model inputs'!U19>'Model inputs'!AA31))),'Model inputs'!AA13*'Model inputs'!AA11,0) -> 8000 | V12: =IF(IF(IF(ISERROR('Model inputs'!V19>'Model inputs'!AA31),'Model inputs'!V19>'Model inputs'!AA31,IF(OR('Model inputs'!V19="",'Model inputs'!AA31=""),"",'Model inputs'!V19>'Model inputs'!AA31))="",FALSE,IF(ISERROR('Model inputs'!V19>'Model inputs'!AA31),'Model inputs'!V19>'Model inputs'!AA31,IF(OR('Model inputs'!V19="",'Model inputs'!AA31=""),"",'Model inputs'!V19>'Model inputs'!AA31))),'Model inputs'!AA13*'Model inputs'!AA11,0) -> 8000 | W12: =IF(IF(IF(ISERROR('Model inputs'!W19>'Model inputs'!AA31),'Model inputs'!W19>'Model inputs'!AA31,IF(OR('Model inputs'!W19="",'Model inputs'!AA31=""),"",'Model inputs'!W19>'Model inputs'!AA31))="",FALSE,IF(ISERROR('Model inputs'!W19>'Model inputs'!AA31),'Model inputs'!W19>'Model inputs'!AA31,IF(OR('Model inputs'!W19="",'Model inputs'!AA31=""),"",'Model inputs'!W19>'Model inputs'!AA31))),'Model inputs'!AA13*'Model inputs'!AA11,0) -> 8000 | X12: =IF(IF(IF(ISERROR('Model inputs'!X19>'Model inputs'!AA31),'Model inputs'!X19>'Model inputs'!AA31,IF(OR('Model inputs'!X19="",'Model inputs'!AA31=""),"",'Model inputs'!X19>'Model inputs'!AA31))="",FALSE,IF(ISERROR('Model inputs'!X19>'Model inputs'!AA31),'Model inputs'!X19>'Model inputs'!AA31,IF(OR('Model inputs'!X19="",'Model inputs'!AA31=""),"",'Model inputs'!X19>'Model inputs'!AA31))),'Model inputs'!AA13*'Model inputs'!AA11,0) -> 8000 | Y12: =IF(IF(IF(ISERROR('Model inputs'!Y19>'Model inputs'!AA31),'Model inputs'!Y19>'Model inputs'!AA31,IF(OR('Model inputs'!Y19="",'Model inputs'!AA31=""),"",'Model inputs'!Y19>'Model inputs'!AA31))="",FALSE,IF(ISERROR('Model inputs'!Y19>'Model inputs'!AA31),'Model inputs'!Y19>'Model inputs'!AA31,IF(OR('Model inputs'!Y19="",'Model inputs'!AA31=""),"",'Model inputs'!Y19>'Model inputs'!AA31))),'Model inputs'!AA13*'Model inputs'!AA11,0) -> 8000 | Z12: =IF(IF(IF(ISERROR('Model inputs'!Z19>'Model inputs'!AA31),'Model inputs'!Z19>'Model inputs'!AA31,IF(OR('Model inputs'!Z19="",'Model inputs'!AA31=""),"",'Model inputs'!Z19>'Model inputs'!AA31))="",FALSE,IF(ISERROR('Model inputs'!Z19>'Model inputs'!AA31),'Model inputs'!Z19>'Model inputs'!AA31,IF(OR('Model inputs'!Z19="",'Model inputs'!AA31=""),"",'Model inputs'!Z19>'Model inputs'!AA31))),'Model inputs'!AA13*'Model inputs'!AA11,0) -> 8000
A13: Founders | AA13: =2 -> 2
