Workbook

Sheet Kedge P&L, Burn & Runway
A1: Kedge P&L, Burn & Runway
A2: Operating Model · Upside
A4: Variable / dimension | B4: 2026-10 | C4: 2026-11 | D4: 2026-12 | E4: 2027-01 | F4: 2027-02 | G4: 2027-03 | H4: 2027-04 | I4: 2027-05 | J4: 2027-06 | K4: 2027-07 | L4: 2027-08 | M4: 2027-09 | N4: 2027-10 | O4: 2027-11 | P4: 2027-12 | Q4: 2028-01 | R4: 2028-02 | S4: 2028-03 | T4: 2028-04 | U4: 2028-05 | V4: 2028-06 | W4: 2028-07 | X4: 2028-08 | Y4: 2028-09
A5: Revenue | B5: ='Model inputs'!C14*'Model inputs'!AA23 -> 900 | C5: ='Model inputs'!D14*'Model inputs'!AA23 -> 2964.7059 | D5: ='Model inputs'!E14*'Model inputs'!AA23 -> 5029.4118 | E5: ='Model inputs'!F14*'Model inputs'!AA23 -> 7094.1176 | F5: ='Model inputs'!G14*'Model inputs'!AA23 -> 9158.8235 | G5: ='Model inputs'!H14*'Model inputs'!AA23 -> 11223.529 | H5: ='Model inputs'!I14*'Model inputs'!AA23 -> 13288.235 | I5: ='Model inputs'!J14*'Model inputs'!AA23 -> 15352.941 | J5: ='Model inputs'!K14*'Model inputs'!AA23 -> 17417.647 | K5: ='Model inputs'!L14*'Model inputs'!AA23 -> 19482.353 | L5: ='Model inputs'!M14*'Model inputs'!AA23 -> 21547.059 | M5: ='Model inputs'!N14*'Model inputs'!AA23 -> 23611.765 | N5: ='Model inputs'!O14*'Model inputs'!AA23 -> 25676.471 | O5: ='Model inputs'!P14*'Model inputs'!AA23 -> 27741.176 | P5: ='Model inputs'!Q14*'Model inputs'!AA23 -> 29805.882 | Q5: ='Model inputs'!R14*'Model inputs'!AA23 -> 31870.588 | R5: ='Model inputs'!S14*'Model inputs'!AA23 -> 33935.294 | S5: ='Model inputs'!T14*'Model inputs'!AA23 -> 36000 | T5: ='Model inputs'!U14*'Model inputs'!AA23 -> 36000 | U5: ='Model inputs'!V14*'Model inputs'!AA23 -> 36000 | V5: ='Model inputs'!W14*'Model inputs'!AA23 -> 36000 | W5: ='Model inputs'!X14*'Model inputs'!AA23 -> 36000 | X5: ='Model inputs'!Y14*'Model inputs'!AA23 -> 36000 | Y5: ='Model inputs'!Z14*'Model inputs'!AA23 -> 36000
A6: AI model costs | B6: ='Model inputs'!C14*'Model inputs'!AA16 -> 40.5 | C6: ='Model inputs'!D14*'Model inputs'!AA16 -> 133.41176 | D6: ='Model inputs'!E14*'Model inputs'!AA16 -> 226.32353 | E6: ='Model inputs'!F14*'Model inputs'!AA16 -> 319.23529 | F6: ='Model inputs'!G14*'Model inputs'!AA16 -> 412.14706 | G6: ='Model inputs'!H14*'Model inputs'!AA16 -> 505.05882 | H6: ='Model inputs'!I14*'Model inputs'!AA16 -> 597.97059 | I6: ='Model inputs'!J14*'Model inputs'!AA16 -> 690.88235 | J6: ='Model inputs'!K14*'Model inputs'!AA16 -> 783.79412 | K6: ='Model inputs'!L14*'Model inputs'!AA16 -> 876.70588 | L6: ='Model inputs'!M14*'Model inputs'!AA16 -> 969.61765 | M6: ='Model inputs'!N14*'Model inputs'!AA16 -> 1062.5294 | N6: ='Model inputs'!O14*'Model inputs'!AA16 -> 1155.4412 | O6: ='Model inputs'!P14*'Model inputs'!AA16 -> 1248.3529 | P6: ='Model inputs'!Q14*'Model inputs'!AA16 -> 1341.2647 | Q6: ='Model inputs'!R14*'Model inputs'!AA16 -> 1434.1765 | R6: ='Model inputs'!S14*'Model inputs'!AA16 -> 1527.0882 | S6: ='Model inputs'!T14*'Model inputs'!AA16 -> 1620 | T6: ='Model inputs'!U14*'Model inputs'!AA16 -> 1620 | U6: ='Model inputs'!V14*'Model inputs'!AA16 -> 1620 | V6: ='Model inputs'!W14*'Model inputs'!AA16 -> 1620 | W6: ='Model inputs'!X14*'Model inputs'!AA16 -> 1620 | X6: ='Model inputs'!Y14*'Model inputs'!AA16 -> 1620 | Y6: ='Model inputs'!Z14*'Model inputs'!AA16 -> 1620
A7: Payment processing | B7: ='Kedge P&L, Burn & Runway'!B5*'Model inputs'!AA22 -> 27 | C7: ='Kedge P&L, Burn & Runway'!C5*'Model inputs'!AA22 -> 88.941176 | D7: ='Kedge P&L, Burn & Runway'!D5*'Model inputs'!AA22 -> 150.88235 | E7: ='Kedge P&L, Burn & Runway'!E5*'Model inputs'!AA22 -> 212.82353 | F7: ='Kedge P&L, Burn & Runway'!F5*'Model inputs'!AA22 -> 274.76471 | G7: ='Kedge P&L, Burn & Runway'!G5*'Model inputs'!AA22 -> 336.70588 | H7: ='Kedge P&L, Burn & Runway'!H5*'Model inputs'!AA22 -> 398.64706 | I7: ='Kedge P&L, Burn & Runway'!I5*'Model inputs'!AA22 -> 460.58824 | J7: ='Kedge P&L, Burn & Runway'!J5*'Model inputs'!AA22 -> 522.52941 | K7: ='Kedge P&L, Burn & Runway'!K5*'Model inputs'!AA22 -> 584.47059 | L7: ='Kedge P&L, Burn & Runway'!L5*'Model inputs'!AA22 -> 646.41176 | M7: ='Kedge P&L, Burn & Runway'!M5*'Model inputs'!AA22 -> 708.35294 | N7: ='Kedge P&L, Burn & Runway'!N5*'Model inputs'!AA22 -> 770.29412 | O7: ='Kedge P&L, Burn & Runway'!O5*'Model inputs'!AA22 -> 832.23529 | P7: ='Kedge P&L, Burn & Runway'!P5*'Model inputs'!AA22 -> 894.17647 | Q7: ='Kedge P&L, Burn & Runway'!Q5*'Model inputs'!AA22 -> 956.11765 | R7: ='Kedge P&L, Burn & Runway'!R5*'Model inputs'!AA22 -> 1018.0588 | S7: ='Kedge P&L, Burn & Runway'!S5*'Model inputs'!AA22 -> 1080 | T7: ='Kedge P&L, Burn & Runway'!T5*'Model inputs'!AA22 -> 1080 | U7: ='Kedge P&L, Burn & Runway'!U5*'Model inputs'!AA22 -> 1080 | V7: ='Kedge P&L, Burn & Runway'!V5*'Model inputs'!AA22 -> 1080 | W7: ='Kedge P&L, Burn & Runway'!W5*'Model inputs'!AA22 -> 1080 | X7: ='Kedge P&L, Burn & Runway'!X5*'Model inputs'!AA22 -> 1080 | Y7: ='Kedge P&L, Burn & Runway'!Y5*'Model inputs'!AA22 -> 1080
A8: Cost of goods sold | B8: ='Kedge P&L, Burn & Runway'!B6+'Kedge P&L, Burn & Runway'!B7 -> 67.5 | C8: ='Kedge P&L, Burn & Runway'!C6+'Kedge P&L, Burn & Runway'!C7 -> 222.35294 | D8: ='Kedge P&L, Burn & Runway'!D6+'Kedge P&L, Burn & Runway'!D7 -> 377.20588 | E8: ='Kedge P&L, Burn & Runway'!E6+'Kedge P&L, Burn & Runway'!E7 -> 532.05882 | F8: ='Kedge P&L, Burn & Runway'!F6+'Kedge P&L, Burn & Runway'!F7 -> 686.91176 | G8: ='Kedge P&L, Burn & Runway'!G6+'Kedge P&L, Burn & Runway'!G7 -> 841.76471 | H8: ='Kedge P&L, Burn & Runway'!H6+'Kedge P&L, Burn & Runway'!H7 -> 996.61765 | I8: ='Kedge P&L, Burn & Runway'!I6+'Kedge P&L, Burn & Runway'!I7 -> 1151.4706 | ... Y8: ='Kedge P&L, Burn & Runway'!Y6+'Kedge P&L, Burn & Runway'!Y7 -> 2700
A9: Gross profit | B9: ='Kedge P&L, Burn & Runway'!B5-'Kedge P&L, Burn & Runway'!B8 -> 832.5 | C9: ='Kedge P&L, Burn & Runway'!C5-'Kedge P&L, Burn & Runway'!C8 -> 2742.3529 | D9: ='Kedge P&L, Burn & Runway'!D5-'Kedge P&L, Burn & Runway'!D8 -> 4652.2059 | E9: ='Kedge P&L, Burn & Runway'!E5-'Kedge P&L, Burn & Runway'!E8 -> 6562.0588 | F9: ='Kedge P&L, Burn & Runway'!F5-'Kedge P&L, Burn & Runway'!F8 -> 8471.9118 | G9: ='Kedge P&L, Burn & Runway'!G5-'Kedge P&L, Burn & Runway'!G8 -> 10381.765 | H9: ='Kedge P&L, Burn & Runway'!H5-'Kedge P&L, Burn & Runway'!H8 -> 12291.618 | I9: ='Kedge P&L, Burn & Runway'!I5-'Kedge P&L, Burn & Runway'!I8 -> 14201.471 | ... Y9: ='Kedge P&L, Burn & Runway'!Y5-'Kedge P&L, Burn & Runway'!Y8 -> 33300
A10: Gross margin | B10: =IFERROR('Kedge P&L, Burn & Runway'!B9/'Kedge P&L, Burn & Runway'!B5,"") -> 0.925 | C10: =IFERROR('Kedge P&L, Burn & Runway'!C9/'Kedge P&L, Burn & Runway'!C5,"") -> 0.925 | D10: =IFERROR('Kedge P&L, Burn & Runway'!D9/'Kedge P&L, Burn & Runway'!D5,"") -> 0.925 | E10: =IFERROR('Kedge P&L, Burn & Runway'!E9/'Kedge P&L, Burn & Runway'!E5,"") -> 0.925 | F10: =IFERROR('Kedge P&L, Burn & Runway'!F9/'Kedge P&L, Burn & Runway'!F5,"") -> 0.925 | G10: =IFERROR('Kedge P&L, Burn & Runway'!G9/'Kedge P&L, Burn & Runway'!G5,"") -> 0.925 | H10: =IFERROR('Kedge P&L, Burn & Runway'!H9/'Kedge P&L, Burn & Runway'!H5,"") -> 0.925 | I10: =IFERROR('Kedge P&L, Burn & Runway'!I9/'Kedge P&L, Burn & Runway'!I5,"") -> 0.925 | ... Y10: =IFERROR('Kedge P&L, Burn & Runway'!Y9/'Kedge P&L, Burn & Runway'!Y5,"") -> 0.925
A11: Founder salaries | B11: =IF(IF(IF(ISERROR('Model inputs'!C17>'Model inputs'!AA27),'Model inputs'!C17>'Model inputs'!AA27,IF(OR('Model inputs'!C17="",'Model inputs'!AA27=""),"",'Model inputs'!C17>'Model inputs'!AA27))="",FALSE,IF(ISERROR('Model inputs'!C17>'Model inputs'!AA27),'Model inputs'!C17>'Model inputs'!AA27,IF(OR('Model inputs'!C17="",'Model inputs'!AA27=""),"",'Model inputs'!C17>'Model inputs'!AA27))),'Model inputs'!AA12*'Model inputs'!AA10,0) -> 0 | C11: =IF(IF(IF(ISERROR('Model inputs'!D17>'Model inputs'!AA27),'Model inputs'!D17>'Model inputs'!AA27,IF(OR('Model inputs'!D17="",'Model inputs'!AA27=""),"",'Model inputs'!D17>'Model inputs'!AA27))="",FALSE,IF(ISERROR('Model inputs'!D17>'Model inputs'!AA27),'Model inputs'!D17>'Model inputs'!AA27,IF(OR('Model inputs'!D17="",'Model inputs'!AA27=""),"",'Model inputs'!D17>'Model inputs'!AA27))),'Model inputs'!AA12*'Model inputs'!AA10,0) -> 0 | D11: =IF(IF(IF(ISERROR('Model inputs'!E17>'Model inputs'!AA27),'Model inputs'!E17>'Model inputs'!AA27,IF(OR('Model inputs'!E17="",'Model inputs'!AA27=""),"",'Model inputs'!E17>'Model inputs'!AA27))="",FALSE,IF(ISERROR('Model inputs'!E17>'Model inputs'!AA27),'Model inputs'!E17>'Model inputs'!AA27,IF(OR('Model inputs'!E17="",'Model inputs'!AA27=""),"",'Model inputs'!E17>'Model inputs'!AA27))),'Model inputs'!AA12*'Model inputs'!AA10,0) -> 0 | E11: =IF(IF(IF(ISERROR('Model inputs'!F17>'Model inputs'!AA27),'Model inputs'!F17>'Model inputs'!AA27,IF(OR('Model inputs'!F17="",'Model inputs'!AA27=""),"",'Model inputs'!F17>'Model inputs'!AA27))="",FALSE,IF(ISERROR('Model inputs'!F17>'Model inputs'!AA27),'Model inputs'!F17>'Model inputs'!AA27,IF(OR('Model inputs'!F17="",'Model inputs'!AA27=""),"",'Model inputs'!F17>'Model inputs'!AA27))),'Model inputs'!AA12*'Model inputs'!AA10,0) -> 0 | F11: =IF(IF(IF(ISERROR('Model inputs'!G17>'Model inputs'!AA27),'Model inputs'!G17>'Model inputs'!AA27,IF(OR('Model inputs'!G17="",'Model inputs'!AA27=""),"",'Model inputs'!G17>'Model inputs'!AA27))="",FALSE,IF(ISERROR('Model inputs'!G17>'Model inputs'!AA27),'Model inputs'!G17>'Model inputs'!AA27,IF(OR('Model inputs'!G17="",'Model inputs'!AA27=""),"",'Model inputs'!G17>'Model inputs'!AA27))),'Model inputs'!AA12*'Model inputs'!AA10,0) -> 0 | G11: =IF(IF(IF(ISERROR('Model inputs'!H17>'Model inputs'!AA27),'Model inputs'!H17>'Model inputs'!AA27,IF(OR('Model inputs'!H17="",'Model inputs'!AA27=""),"",'Model inputs'!H17>'Model inputs'!AA27))="",FALSE,IF(ISERROR('Model inputs'!H17>'Model inputs'!AA27),'Model inputs'!H17>'Model inputs'!AA27,IF(OR('Model inputs'!H17="",'Model inputs'!AA27=""),"",'Model inputs'!H17>'Model inputs'!AA27))),'Model inputs'!AA12*'Model inputs'!AA10,0) -> 0 | H11: =IF(IF(IF(ISERROR('Model inputs'!I17>'Model inputs'!AA27),'Model inputs'!I17>'Model inputs'!AA27,IF(OR('Model inputs'!I17="",'Model inputs'!AA27=""),"",'Model inputs'!I17>'Model inputs'!AA27))="",FALSE,IF(ISERROR('Model inputs'!I17>'Model inputs'!AA27),'Model inputs'!I17>'Model inputs'!AA27,IF(OR('Model inputs'!I17="",'Model inputs'!AA27=""),"",'Model inputs'!I17>'Model inputs'!AA27))),'Model inputs'!AA12*'Model inputs'!AA10,0) -> 8000 | I11: =IF(IF(IF(ISERROR('Model inputs'!J17>'Model inputs'!AA27),'Model inputs'!J17>'Model inputs'!AA27,IF(OR('Model inputs'!J17="",'Model inputs'!AA27=""),"",'Model inputs'!J17>'Model inputs'!AA27))="",FALSE,IF(ISERROR('Model inputs'!J17>'Model inputs'!AA27),'Model inputs'!J17>'Model inputs'!AA27,IF(OR('Model inputs'!J17="",'Model inputs'!AA27=""),"",'Model inputs'!J17>'Model inputs'!AA27))),'Model inputs'!AA12*'Model inputs'!AA10,0) -> 8000 | J11: =IF(IF(IF(ISERROR('Model inputs'!K17>'Model inputs'!AA27),'Model inputs'!K17>'Model inputs'!AA27,IF(OR('Model inputs'!K17="",'Model inputs'!AA27=""),"",'Model inputs'!K17>'Model inputs'!AA27))="",FALSE,IF(ISERROR('Model inputs'!K17>'Model inputs'!AA27),'Model inputs'!K17>'Model inputs'!AA27,IF(OR('Model inputs'!K17="",'Model inputs'!AA27=""),"",'Model inputs'!K17>'Model inputs'!AA27))),'Model inputs'!AA12*'Model inputs'!AA10,0) -> 8000 | K11: =IF(IF(IF(ISERROR('Model inputs'!L17>'Model inputs'!AA27),'Model inputs'!L17>'Model inputs'!AA27,IF(OR('Model inputs'!L17="",'Model inputs'!AA27=""),"",'Model inputs'!L17>'Model inputs'!AA27))="",FALSE,IF(ISERROR('Model inputs'!L17>'Model inputs'!AA27),'Model inputs'!L17>'Model inputs'!AA27,IF(OR('Model inputs'!L17="",'Model inputs'!AA27=""),"",'Model inputs'!L17>'Model inputs'!AA27))),'Model inputs'!AA12*'Model inputs'!AA10,0) -> 8000 | L11: =IF(IF(IF(ISERROR('Model inputs'!M17>'Model inputs'!AA27),'Model inputs'!M17>'Model inputs'!AA27,IF(OR('Model inputs'!M17="",'Model inputs'!AA27=""),"",'Model inputs'!M17>'Model inputs'!AA27))="",FALSE,IF(ISERROR('Model inputs'!M17>'Model inputs'!AA27),'Model inputs'!M17>'Model inputs'!AA27,IF(OR('Model inputs'!M17="",'Model inputs'!AA27=""),"",'Model inputs'!M17>'Model inputs'!AA27))),'Model inputs'!AA12*'Model inputs'!AA10,0) -> 8000 | M11: =IF(IF(IF(ISERROR('Model inputs'!N17>'Model inputs'!AA27),'Model inputs'!N17>'Model inputs'!AA27,IF(OR('Model inputs'!N17="",'Model inputs'!AA27=""),"",'Model inputs'!N17>'Model inputs'!AA27))="",FALSE,IF(ISERROR('Model inputs'!N17>'Model inputs'!AA27),'Model inputs'!N17>'Model inputs'!AA27,IF(OR('Model inputs'!N17="",'Model inputs'!AA27=""),"",'Model inputs'!N17>'Model inputs'!AA27))),'Model inputs'!AA12*'Model inputs'!AA10,0) -> 8000 | N11: =IF(IF(IF(ISERROR('Model inputs'!O17>'Model inputs'!AA27),'Model inputs'!O17>'Model inputs'!AA27,IF(OR('Model inputs'!O17="",'Model inputs'!AA27=""),"",'Model inputs'!O17>'Model inputs'!AA27))="",FALSE,IF(ISERROR('Model inputs'!O17>'Model inputs'!AA27),'Model inputs'!O17>'Model inputs'!AA27,IF(OR('Model inputs'!O17="",'Model inputs'!AA27=""),"",'Model inputs'!O17>'Model inputs'!AA27))),'Model inputs'!AA12*'Model inputs'!AA10,0) -> 8000 | O11: =IF(IF(IF(ISERROR('Model inputs'!P17>'Model inputs'!AA27),'Model inputs'!P17>'Model inputs'!AA27,IF(OR('Model inputs'!P17="",'Model inputs'!AA27=""),"",'Model inputs'!P17>'Model inputs'!AA27))="",FALSE,IF(ISERROR('Model inputs'!P17>'Model inputs'!AA27),'Model inputs'!P17>'Model inputs'!AA27,IF(OR('Model inputs'!P17="",'Model inputs'!AA27=""),"",'Model inputs'!P17>'Model inputs'!AA27))),'Model inputs'!AA12*'Model inputs'!AA10,0) -> 8000 | P11: =IF(IF(IF(ISERROR('Model inputs'!Q17>'Model inputs'!AA27),'Model inputs'!Q17>'Model inputs'!AA27,IF(OR('Model inputs'!Q17="",'Model inputs'!AA27=""),"",'Model inputs'!Q17>'Model inputs'!AA27))="",FALSE,IF(ISERROR('Model inputs'!Q17>'Model inputs'!AA27),'Model inputs'!Q17>'Model inputs'!AA27,IF(OR('Model inputs'!Q17="",'Model inputs'!AA27=""),"",'Model inputs'!Q17>'Model inputs'!AA27))),'Model inputs'!AA12*'Model inputs'!AA10,0) -> 8000 | Q11: =IF(IF(IF(ISERROR('Model inputs'!R17>'Model inputs'!AA27),'Model inputs'!R17>'Model inputs'!AA27,IF(OR('Model inputs'!R17="",'Model inputs'!AA27=""),"",'Model inputs'!R17>'Model inputs'!AA27))="",FALSE,IF(ISERROR('Model inputs'!R17>'Model inputs'!AA27),'Model inputs'!R17>'Model inputs'!AA27,IF(OR('Model inputs'!R17="",'Model inputs'!AA27=""),"",'Model inputs'!R17>'Model inputs'!AA27))),'Model inputs'!AA12*'Model inputs'!AA10,0) -> 8000 | R11: =IF(IF(IF(ISERROR('Model inputs'!S17>'Model inputs'!AA27),'Model inputs'!S17>'Model inputs'!AA27,IF(OR('Model inputs'!S17="",'Model inputs'!AA27=""),"",'Model inputs'!S17>'Model inputs'!AA27))="",FALSE,IF(ISERROR('Model inputs'!S17>'Model inputs'!AA27),'Model inputs'!S17>'Model inputs'!AA27,IF(OR('Model inputs'!S17="",'Model inputs'!AA27=""),"",'Model inputs'!S17>'Model inputs'!AA27))),'Model inputs'!AA12*'Model inputs'!AA10,0) -> 8000 | S11: =IF(IF(IF(ISERROR('Model inputs'!T17>'Model inputs'!AA27),'Model inputs'!T17>'Model inputs'!AA27,IF(OR('Model inputs'!T17="",'Model inputs'!AA27=""),"",'Model inputs'!T17>'Model inputs'!AA27))="",FALSE,IF(ISERROR('Model inputs'!T17>'Model inputs'!AA27),'Model inputs'!T17>'Model inputs'!AA27,IF(OR('Model inputs'!T17="",'Model inputs'!AA27=""),"",'Model inputs'!T17>'Model inputs'!AA27))),'Model inputs'!AA12*'Model inputs'!AA10,0) -> 8000 | T11: =IF(IF(IF(ISERROR('Model inputs'!U17>'Model inputs'!AA27),'Model inputs'!U17>'Model inputs'!AA27,IF(OR('Model inputs'!U17="",'Model inputs'!AA27=""),"",'Model inputs'!U17>'Model inputs'!AA27))="",FALSE,IF(ISERROR('Model inputs'!U17>'Model inputs'!AA27),'Model inputs'!U17>'Model inputs'!AA27,IF(OR('Model inputs'!U17="",'Model inputs'!AA27=""),"",'Model inputs'!U17>'Model inputs'!AA27))),'Model inputs'!AA12*'Model inputs'!AA10,0) -> 8000 | U11: =IF(IF(IF(ISERROR('Model inputs'!V17>'Model inputs'!AA27),'Model inputs'!V17>'Model inputs'!AA27,IF(OR('Model inputs'!V17="",'Model inputs'!AA27=""),"",'Model inputs'!V17>'Model inputs'!AA27))="",FALSE,IF(ISERROR('Model inputs'!V17>'Model inputs'!AA27),'Model inputs'!V17>'Model inputs'!AA27,IF(OR('Model inputs'!V17="",'Model inputs'!AA27=""),"",'Model inputs'!V17>'Model inputs'!AA27))),'Model inputs'!AA12*'Model inputs'!AA10,0) -> 8000 | V11: =IF(IF(IF(ISERROR('Model inputs'!W17>'Model inputs'!AA27),'Model inputs'!W17>'Model inputs'!AA27,IF(OR('Model inputs'!W17="",'Model inputs'!AA27=""),"",'Model inputs'!W17>'Model inputs'!AA27))="",FALSE,IF(ISERROR('Model inputs'!W17>'Model inputs'!AA27),'Model inputs'!W17>'Model inputs'!AA27,IF(OR('Model inputs'!W17="",'Model inputs'!AA27=""),"",'Model inputs'!W17>'Model inputs'!AA27))),'Model inputs'!AA12*'Model inputs'!AA10,0) -> 8000 | W11: =IF(IF(IF(ISERROR('Model inputs'!X17>'Model inputs'!AA27),'Model inputs'!X17>'Model inputs'!AA27,IF(OR('Model inputs'!X17="",'Model inputs'!AA27=""),"",'Model inputs'!X17>'Model inputs'!AA27))="",FALSE,IF(ISERROR('Model inputs'!X17>'Model inputs'!AA27),'Model inputs'!X17>'Model inputs'!AA27,IF(OR('Model inputs'!X17="",'Model inputs'!AA27=""),"",'Model inputs'!X17>'Model inputs'!AA27))),'Model inputs'!AA12*'Model inputs'!AA10,0) -> 8000 | X11: =IF(IF(IF(ISERROR('Model inputs'!Y17>'Model inputs'!AA27),'Model inputs'!Y17>'Model inputs'!AA27,IF(OR('Model inputs'!Y17="",'Model inputs'!AA27=""),"",'Model inputs'!Y17>'Model inputs'!AA27))="",FALSE,IF(ISERROR('Model inputs'!Y17>'Model inputs'!AA27),'Model inputs'!Y17>'Model inputs'!AA27,IF(OR('Model inputs'!Y17="",'Model inputs'!AA27=""),"",'Model inputs'!Y17>'Model inputs'!AA27))),'Model inputs'!AA12*'Model inputs'!AA10,0) -> 8000 | Y11: =IF(IF(IF(ISERROR('Model inputs'!Z17>'Model inputs'!AA27),'Model inputs'!Z17>'Model inputs'!AA27,IF(OR('Model inputs'!Z17="",'Model inputs'!AA27=""),"",'Model inputs'!Z17>'Model inputs'!AA27))="",FALSE,IF(ISERROR('Model inputs'!Z17>'Model inputs'!AA27),'Model inputs'!Z17>'Model inputs'!AA27,IF(OR('Model inputs'!Z17="",'Model inputs'!AA27=""),"",'Model inputs'!Z17>'Model inputs'!AA27))),'Model inputs'!AA12*'Model inputs'!AA10,0) -> 8000
A12: Software and tools | B12: =IF('Model inputs'!AA26="","",'Model inputs'!AA26) -> 200 | C12: =IF('Model inputs'!AA26="","",'Model inputs'!AA26) -> 200 | D12: =IF('Model inputs'!AA26="","",'Model inputs'!AA26) -> 200 | E12: =IF('Model inputs'!AA26="","",'Model inputs'!AA26) -> 200 | F12: =IF('Model inputs'!AA26="","",'Model inputs'!AA26) -> 200 | G12: =IF('Model inputs'!AA26="","",'Model inputs'!AA26) -> 200 | H12: =IF('Model inputs'!AA26="","",'Model inputs'!AA26) -> 200 | I12: =IF('Model inputs'!AA26="","",'Model inputs'!AA26) -> 200 | J12: =IF('Model inputs'!AA26="","",'Model inputs'!AA26) -> 200 | K12: =IF('Model inputs'!AA26="","",'Model inputs'!AA26) -> 200 | L12: =IF('Model inputs'!AA26="","",'Model inputs'!AA26) -> 200 | M12: =IF('Model inputs'!AA26="","",'Model inputs'!AA26) -> 200 | N12: =IF('Model inputs'!AA26="","",'Model inputs'!AA26) -> 200 | O12: =IF('Model inputs'!AA26="","",'Model inputs'!AA26) -> 200 | P12: =IF('Model inputs'!AA26="","",'Model inputs'!AA26) -> 200 | Q12: =IF('Model inputs'!AA26="","",'Model inputs'!AA26) -> 200 | R12: =IF('Model inputs'!AA26="","",'Model inputs'!AA26) -> 200 | S12: =IF('Model inputs'!AA26="","",'Model inputs'!AA26) -> 200 | T12: =IF('Model inputs'!AA26="","",'Model inputs'!AA26) -> 200 | U12: =IF('Model inputs'!AA26="","",'Model inputs'!AA26) -> 200 | V12: =IF('Model inputs'!AA26="","",'Model inputs'!AA26) -> 200 | W12: =IF('Model inputs'!AA26="","",'Model inputs'!AA26) -> 200 | X12: =IF('Model inputs'!AA26="","",'Model inputs'!AA26) -> 200 | Y12: =IF('Model inputs'!AA26="","",'Model inputs'!AA26) -> 200
A13: Operating expenses | B13: ='Kedge P&L, Burn & Runway'!B11+'Kedge P&L, Burn & Runway'!B12 -> 200 | C13: ='Kedge P&L, Burn & Runway'!C11+'Kedge P&L, Burn & Runway'!C12 -> 200 | D13: ='Kedge P&L, Burn & Runway'!D11+'Kedge P&L, Burn & Runway'!D12 -> 200 | E13: ='Kedge P&L, Burn & Runway'!E11+'Kedge P&L, Burn & Runway'!E12 -> 200 | F13: ='Kedge P&L, Burn & Runway'!F11+'Kedge P&L, Burn & Runway'!F12 -> 200 | G13: ='Kedge P&L, Burn & Runway'!G11+'Kedge P&L, Burn & Runway'!G12 -> 200 | H13: ='Kedge P&L, Burn & Runway'!H11+'Kedge P&L, Burn & Runway'!H12 -> 8200 | I13: ='Kedge P&L, Burn & Runway'!I11+'Kedge P&L, Burn & Runway'!I12 -> 8200 | ... Y13: ='Kedge P&L, Burn & Runway'!Y11+'Kedge P&L, Burn & Runway'!Y12 -> 8200
A14: Operating income | B14: ='Kedge P&L, Burn & Runway'!B9-'Kedge P&L, Burn & Runway'!B13 -> 632.5 | C14: ='Kedge P&L, Burn & Runway'!C9-'Kedge P&L, Burn & Runway'!C13 -> 2542.3529 | D14: ='Kedge P&L, Burn & Runway'!D9-'Kedge P&L, Burn & Runway'!D13 -> 4452.2059 | E14: ='Kedge P&L, Burn & Runway'!E9-'Kedge P&L, Burn & Runway'!E13 -> 6362.0588 | F14: ='Kedge P&L, Burn & Runway'!F9-'Kedge P&L, Burn & Runway'!F13 -> 8271.9118 | G14: ='Kedge P&L, Burn & Runway'!G9-'Kedge P&L, Burn & Runway'!G13 -> 10181.765 | H14: ='Kedge P&L, Burn & Runway'!H9-'Kedge P&L, Burn & Runway'!H13 -> 4091.6176 | I14: ='Kedge P&L, Burn & Runway'!I9-'Kedge P&L, Burn & Runway'!I13 -> 6001.4706 | ... Y14: ='Kedge P&L, Burn & Runway'!Y9-'Kedge P&L, Burn & Runway'!Y13 -> 25100
A15: Net burn | B15: =-'Kedge P&L, Burn & Runway'!B14 -> -632.5 | C15: =-'Kedge P&L, Burn & Runway'!C14 -> -2542.3529 | D15: =-'Kedge P&L, Burn & Runway'!D14 -> -4452.2059 | E15: =-'Kedge P&L, Burn & Runway'!E14 -> -6362.0588 | F15: =-'Kedge P&L, Burn & Runway'!F14 -> -8271.9118 | G15: =-'Kedge P&L, Burn & Runway'!G14 -> -10181.765 | H15: =-'Kedge P&L, Burn & Runway'!H14 -> -4091.6176 | I15: =-'Kedge P&L, Burn & Runway'!I14 -> -6001.4706 | ... Y15: =-'Kedge P&L, Burn & Runway'!Y14 -> -25100
A16: Equity raised | B16: 0 | C16: 0 | D16: 0 | E16: 0 | F16: 0 | G16: 0 | H16: =0 -> 0 | I16: 0 | J16: 0 | K16: 0 | L16: 0 | M16: 0 | N16: 0 | O16: 0 | P16: 0 | Q16: 0 | R16: 0 | S16: 0 | T16: 0 | U16: 0 | V16: 0 | W16: 0 | X16: 0 | Y16: 0
A17: Cash balance | B17: ='Model inputs'!B7-'Kedge P&L, Burn & Runway'!B15+'Kedge P&L, Burn & Runway'!B16 -> 632.5 | C17: ='Kedge P&L, Burn & Runway'!B17-'Kedge P&L, Burn & Runway'!C15+'Kedge P&L, Burn & Runway'!C16 -> 3174.8529 | D17: ='Kedge P&L, Burn & Runway'!C17-'Kedge P&L, Burn & Runway'!D15+'Kedge P&L, Burn & Runway'!D16 -> 7627.0588 | E17: ='Kedge P&L, Burn & Runway'!D17-'Kedge P&L, Burn & Runway'!E15+'Kedge P&L, Burn & Runway'!E16 -> 13989.118 | F17: ='Kedge P&L, Burn & Runway'!E17-'Kedge P&L, Burn & Runway'!F15+'Kedge P&L, Burn & Runway'!F16 -> 22261.029 | G17: ='Kedge P&L, Burn & Runway'!F17-'Kedge P&L, Burn & Runway'!G15+'Kedge P&L, Burn & Runway'!G16 -> 32442.794 | H17: ='Kedge P&L, Burn & Runway'!G17-'Kedge P&L, Burn & Runway'!H15+'Kedge P&L, Burn & Runway'!H16 -> 36534.412 | I17: ='Kedge P&L, Burn & Runway'!H17-'Kedge P&L, Burn & Runway'!I15+'Kedge P&L, Burn & Runway'!I16 -> 42535.882 | J17: ='Kedge P&L, Burn & Runway'!I17-'Kedge P&L, Burn & Runway'!J15+'Kedge P&L, Burn & Runway'!J16 -> 50447.206 | ... Y17: ='Kedge P&L, Burn & Runway'!X17-'Kedge P&L, Burn & Runway'!Y15+'Kedge P&L, Burn & Runway'!Y16 -> 358192.5
A18: Funding needed to date | B18: =IF(IF(IF(ISERROR(-'Kedge P&L, Burn & Runway'!B17>'Model inputs'!B13),-'Kedge P&L, Burn & Runway'!B17>'Model inputs'!B13,IF('Model inputs'!B13="","",-'Kedge P&L, Burn & Runway'!B17>'Model inputs'!B13))="",FALSE,IF(ISERROR(-'Kedge P&L, Burn & Runway'!B17>'Model inputs'!B13),-'Kedge P&L, Burn & Runway'!B17>'Model inputs'!B13,IF('Model inputs'!B13="","",-'Kedge P&L, Burn & Runway'!B17>'Model inputs'!B13))),-'Kedge P&L, Burn & Runway'!B17,IF('Model inputs'!B13="","",'Model inputs'!B13)) -> 0 | C18: =IF(IF(IF(ISERROR(-'Kedge P&L, Burn & Runway'!C17>'Kedge P&L, Burn & Runway'!B18),-'Kedge P&L, Burn & Runway'!C17>'Kedge P&L, Burn & Runway'!B18,IF('Kedge P&L, Burn & Runway'!B18="","",-'Kedge P&L, Burn & Runway'!C17>'Kedge P&L, Burn & Runway'!B18))="",FALSE,IF(ISERROR(-'Kedge P&L, Burn & Runway'!C17>'Kedge P&L, Burn & Runway'!B18),-'Kedge P&L, Burn & Runway'!C17>'Kedge P&L, Burn & Runway'!B18,IF('Kedge P&L, Burn & Runway'!B18="","",-'Kedge P&L, Burn & Runway'!C17>'Kedge P&L, Burn & Runway'!B18))),-'Kedge P&L, Burn & Runway'!C17,IF('Kedge P&L, Burn & Runway'!B18="","",'Kedge P&L, Burn & Runway'!B18)) -> 0 | D18: =IF(IF(IF(ISERROR(-'Kedge P&L, Burn & Runway'!D17>'Kedge P&L, Burn & Runway'!C18),-'Kedge P&L, Burn & Runway'!D17>'Kedge P&L, Burn & Runway'!C18,IF('Kedge P&L, Burn & Runway'!C18="","",-'Kedge P&L, Burn & Runway'!D17>'Kedge P&L, Burn & Runway'!C18))="",FALSE,IF(ISERROR(-'Kedge P&L, Burn & Runway'!D17>'Kedge P&L, Burn & Runway'!C18),-'Kedge P&L, Burn & Runway'!D17>'Kedge P&L, Burn & Runway'!C18,IF('Kedge P&L, Burn & Runway'!C18="","",-'Kedge P&L, Burn & Runway'!D17>'Kedge P&L, Burn & Runway'!C18))),-'Kedge P&L, Burn & Runway'!D17,IF('Kedge P&L, Burn & Runway'!C18="","",'Kedge P&L, Burn & Runway'!C18)) -> 0 | E18: =IF(IF(IF(ISERROR(-'Kedge P&L, Burn & Runway'!E17>'Kedge P&L, Burn & Runway'!D18),-'Kedge P&L, Burn & Runway'!E17>'Kedge P&L, Burn & Runway'!D18,IF('Kedge P&L, Burn & Runway'!D18="","",-'Kedge P&L, Burn & Runway'!E17>'Kedge P&L, Burn & Runway'!D18))="",FALSE,IF(ISERROR(-'Kedge P&L, Burn & Runway'!E17>'Kedge P&L, Burn & Runway'!D18),-'Kedge P&L, Burn & Runway'!E17>'Kedge P&L, Burn & Runway'!D18,IF('Kedge P&L, Burn & Runway'!D18="","",-'Kedge P&L, Burn & Runway'!E17>'Kedge P&L, Burn & Runway'!D18))),-'Kedge P&L, Burn & Runway'!E17,IF('Kedge P&L, Burn & Runway'!D18="","",'Kedge P&L, Burn & Runway'!D18)) -> 0 | F18: =IF(IF(IF(ISERROR(-'Kedge P&L, Burn & Runway'!F17>'Kedge P&L, Burn & Runway'!E18),-'Kedge P&L, Burn & Runway'!F17>'Kedge P&L, Burn & Runway'!E18,IF('Kedge P&L, Burn & Runway'!E18="","",-'Kedge P&L, Burn & Runway'!F17>'Kedge P&L, Burn & Runway'!E18))="",FALSE,IF(ISERROR(-'Kedge P&L, Burn & Runway'!F17>'Kedge P&L, Burn & Runway'!E18),-'Kedge P&L, Burn & Runway'!F17>'Kedge P&L, Burn & Runway'!E18,IF('Kedge P&L, Burn & Runway'!E18="","",-'Kedge P&L, Burn & Runway'!F17>'Kedge P&L, Burn & Runway'!E18))),-'Kedge P&L, Burn & Runway'!F17,IF('Kedge P&L, Burn & Runway'!E18="","",'Kedge P&L, Burn & Runway'!E18)) -> 0 | G18: =IF(IF(IF(ISERROR(-'Kedge P&L, Burn & Runway'!G17>'Kedge P&L, Burn & Runway'!F18),-'Kedge P&L, Burn & Runway'!G17>'Kedge P&L, Burn & Runway'!F18,IF('Kedge P&L, Burn & Runway'!F18="","",-'Kedge P&L, Burn & Runway'!G17>'Kedge P&L, Burn & Runway'!F18))="",FALSE,IF(ISERROR(-'Kedge P&L, Burn & Runway'!G17>'Kedge P&L, Burn & Runway'!F18),-'Kedge P&L, Burn & Runway'!G17>'Kedge P&L, Burn & Runway'!F18,IF('Kedge P&L, Burn & Runway'!F18="","",-'Kedge P&L, Burn & Runway'!G17>'Kedge P&L, Burn & Runway'!F18))),-'Kedge P&L, Burn & Runway'!G17,IF('Kedge P&L, Burn & Runway'!F18="","",'Kedge P&L, Burn & Runway'!F18)) -> 0 | H18: =IF(IF(IF(ISERROR(-'Kedge P&L, Burn & Runway'!H17>'Kedge P&L, Burn & Runway'!G18),-'Kedge P&L, Burn & Runway'!H17>'Kedge P&L, Burn & Runway'!G18,IF('Kedge P&L, Burn & Runway'!G18="","",-'Kedge P&L, Burn & Runway'!H17>'Kedge P&L, Burn & Runway'!G18))="",FALSE,IF(ISERROR(-'Kedge P&L, Burn & Runway'!H17>'Kedge P&L, Burn & Runway'!G18),-'Kedge P&L, Burn & Runway'!H17>'Kedge P&L, Burn & Runway'!G18,IF('Kedge P&L, Burn & Runway'!G18="","",-'Kedge P&L, Burn & Runway'!H17>'Kedge P&L, Burn & Runway'!G18))),-'Kedge P&L, Burn & Runway'!H17,IF('Kedge P&L, Burn & Runway'!G18="","",'Kedge P&L, Burn & Runway'!G18)) -> 0 | I18: =IF(IF(IF(ISERROR(-'Kedge P&L, Burn & Runway'!I17>'Kedge P&L, Burn & Runway'!H18),-'Kedge P&L, Burn & Runway'!I17>'Kedge P&L, Burn & Runway'!H18,IF('Kedge P&L, Burn & Runway'!H18="","",-'Kedge P&L, Burn & Runway'!I17>'Kedge P&L, Burn & Runway'!H18))="",FALSE,IF(ISERROR(-'Kedge P&L, Burn & Runway'!I17>'Kedge P&L, Burn & Runway'!H18),-'Kedge P&L, Burn & Runway'!I17>'Kedge P&L, Burn & Runway'!H18,IF('Kedge P&L, Burn & Runway'!H18="","",-'Kedge P&L, Burn & Runway'!I17>'Kedge P&L, Burn & Runway'!H18))),-'Kedge P&L, Burn & Runway'!I17,IF('Kedge P&L, Burn & Runway'!H18="","",'Kedge P&L, Burn & Runway'!H18)) -> 0 | J18: =IF(IF(IF(ISERROR(-'Kedge P&L, Burn & Runway'!J17>'Kedge P&L, Burn & Runway'!I18),-'Kedge P&L, Burn & Runway'!J17>'Kedge P&L, Burn & Runway'!I18,IF('Kedge P&L, Burn & Runway'!I18="","",-'Kedge P&L, Burn & Runway'!J17>'Kedge P&L, Burn & Runway'!I18))="",FALSE,IF(ISERROR(-'Kedge P&L, Burn & Runway'!J17>'Kedge P&L, Burn & Runway'!I18),-'Kedge P&L, Burn & Runway'!J17>'Kedge P&L, Burn & Runway'!I18,IF('Kedge P&L, Burn & Runway'!I18="","",-'Kedge P&L, Burn & Runway'!J17>'Kedge P&L, Burn & Runway'!I18))),-'Kedge P&L, Burn & Runway'!J17,IF('Kedge P&L, Burn & Runway'!I18="","",'Kedge P&L, Burn & Runway'!I18)) -> 0 | ... Y18: =IF(IF(IF(ISERROR(-'Kedge P&L, Burn & Runway'!Y17>'Kedge P&L, Burn & Runway'!X18),-'Kedge P&L, Burn & Runway'!Y17>'Kedge P&L, Burn & Runway'!X18,IF('Kedge P&L, Burn & Runway'!X18="","",-'Kedge P&L, Burn & Runway'!Y17>'Kedge P&L, Burn & Runway'!X18))="",FALSE,IF(ISERROR(-'Kedge P&L, Burn & Runway'!Y17>'Kedge P&L, Burn & Runway'!X18),-'Kedge P&L, Burn & Runway'!Y17>'Kedge P&L, Burn & Runway'!X18,IF('Kedge P&L, Burn & Runway'!X18="","",-'Kedge P&L, Burn & Runway'!Y17>'Kedge P&L, Burn & Runway'!X18))),-'Kedge P&L, Burn & Runway'!Y17,IF('Kedge P&L, Burn & Runway'!X18="","",'Kedge P&L, Burn & Runway'!X18)) -> 0
A19: Runway (months) | B19: =IF(IF(IF(ISERROR('Kedge P&L, Burn & Runway'!B15>0),'Kedge P&L, Burn & Runway'!B15>0,IF('Kedge P&L, Burn & Runway'!B15="","",'Kedge P&L, Burn & Runway'!B15>0))="",FALSE,IF(ISERROR('Kedge P&L, Burn & Runway'!B15>0),'Kedge P&L, Burn & Runway'!B15>0,IF('Kedge P&L, Burn & Runway'!B15="","",'Kedge P&L, Burn & Runway'!B15>0))),IF(IF(IF(ISERROR('Kedge P&L, Burn & Runway'!B17>0),'Kedge P&L, Burn & Runway'!B17>0,IF('Kedge P&L, Burn & Runway'!B17="","",'Kedge P&L, Burn & Runway'!B17>0))="",FALSE,IF(ISERROR('Kedge P&L, Burn & Runway'!B17>0),'Kedge P&L, Burn & Runway'!B17>0,IF('Kedge P&L, Burn & Runway'!B17="","",'Kedge P&L, Burn & Runway'!B17>0))),'Kedge P&L, Burn & Runway'!B17/'Kedge P&L, Burn & Runway'!B15,0),"") | C19: =IF(IF(IF(ISERROR('Kedge P&L, Burn & Runway'!C15>0),'Kedge P&L, Burn & Runway'!C15>0,IF('Kedge P&L, Burn & Runway'!C15="","",'Kedge P&L, Burn & Runway'!C15>0))="",FALSE,IF(ISERROR('Kedge P&L, Burn & Runway'!C15>0),'Kedge P&L, Burn & Runway'!C15>0,IF('Kedge P&L, Burn & Runway'!C15="","",'Kedge P&L, Burn & Runway'!C15>0))),IF(IF(IF(ISERROR('Kedge P&L, Burn & Runway'!C17>0),'Kedge P&L, Burn & Runway'!C17>0,IF('Kedge P&L, Burn & Runway'!C17="","",'Kedge P&L, Burn & Runway'!C17>0))="",FALSE,IF(ISERROR('Kedge P&L, Burn & Runway'!C17>0),'Kedge P&L, Burn & Runway'!C17>0,IF('Kedge P&L, Burn & Runway'!C17="","",'Kedge P&L, Burn & Runway'!C17>0))),'Kedge P&L, Burn & Runway'!C17/'Kedge P&L, Burn & Runway'!C15,0),"") | D19: =IF(IF(IF(ISERROR('Kedge P&L, Burn & Runway'!D15>0),'Kedge P&L, Burn & Runway'!D15>0,IF('Kedge P&L, Burn & Runway'!D15="","",'Kedge P&L, Burn & Runway'!D15>0))="",FALSE,IF(ISERROR('Kedge P&L, Burn & Runway'!D15>0),'Kedge P&L, Burn & Runway'!D15>0,IF('Kedge P&L, Burn & Runway'!D15="","",'Kedge P&L, Burn & Runway'!D15>0))),IF(IF(IF(ISERROR('Kedge P&L, Burn & Runway'!D17>0),'Kedge P&L, Burn & Runway'!D17>0,IF('Kedge P&L, Burn & Runway'!D17="","",'Kedge P&L, Burn & Runway'!D17>0))="",FALSE,IF(ISERROR('Kedge P&L, Burn & Runway'!D17>0),'Kedge P&L, Burn & Runway'!D17>0,IF('Kedge P&L, Burn & Runway'!D17="","",'Kedge P&L, Burn & Runway'!D17>0))),'Kedge P&L, Burn & Runway'!D17/'Kedge P&L, Burn & Runway'!D15,0),"") | E19: =IF(IF(IF(ISERROR('Kedge P&L, Burn & Runway'!E15>0),'Kedge P&L, Burn & Runway'!E15>0,IF('Kedge P&L, Burn & Runway'!E15="","",'Kedge P&L, Burn & Runway'!E15>0))="",FALSE,IF(ISERROR('Kedge P&L, Burn & Runway'!E15>0),'Kedge P&L, Burn & Runway'!E15>0,IF('Kedge P&L, Burn & Runway'!E15="","",'Kedge P&L, Burn & Runway'!E15>0))),IF(IF(IF(ISERROR('Kedge P&L, Burn & Runway'!E17>0),'Kedge P&L, Burn & Runway'!E17>0,IF('Kedge P&L, Burn & Runway'!E17="","",'Kedge P&L, Burn & Runway'!E17>0))="",FALSE,IF(ISERROR('Kedge P&L, Burn & Runway'!E17>0),'Kedge P&L, Burn & Runway'!E17>0,IF('Kedge P&L, Burn & Runway'!E17="","",'Kedge P&L, Burn & Runway'!E17>0))),'Kedge P&L, Burn & Runway'!E17/'Kedge P&L, Burn & Runway'!E15,0),"") | F19: =IF(IF(IF(ISERROR('Kedge P&L, Burn & Runway'!F15>0),'Kedge P&L, Burn & Runway'!F15>0,IF('Kedge P&L, Burn & Runway'!F15="","",'Kedge P&L, Burn & Runway'!F15>0))="",FALSE,IF(ISERROR('Kedge P&L, Burn & Runway'!F15>0),'Kedge P&L, Burn & Runway'!F15>0,IF('Kedge P&L, Burn & Runway'!F15="","",'Kedge P&L, Burn & Runway'!F15>0))),IF(IF(IF(ISERROR('Kedge P&L, Burn & Runway'!F17>0),'Kedge P&L, Burn & Runway'!F17>0,IF('Kedge P&L, Burn & Runway'!F17="","",'Kedge P&L, Burn & Runway'!F17>0))="",FALSE,IF(ISERROR('Kedge P&L, Burn & Runway'!F17>0),'Kedge P&L, Burn & Runway'!F17>0,IF('Kedge P&L, Burn & Runway'!F17="","",'Kedge P&L, Burn & Runway'!F17>0))),'Kedge P&L, Burn & Runway'!F17/'Kedge P&L, Burn & Runway'!F15,0),"") | G19: =IF(IF(IF(ISERROR('Kedge P&L, Burn & Runway'!G15>0),'Kedge P&L, Burn & Runway'!G15>0,IF('Kedge P&L, Burn & Runway'!G15="","",'Kedge P&L, Burn & Runway'!G15>0))="",FALSE,IF(ISERROR('Kedge P&L, Burn & Runway'!G15>0),'Kedge P&L, Burn & Runway'!G15>0,IF('Kedge P&L, Burn & Runway'!G15="","",'Kedge P&L, Burn & Runway'!G15>0))),IF(IF(IF(ISERROR('Kedge P&L, Burn & Runway'!G17>0),'Kedge P&L, Burn & Runway'!G17>0,IF('Kedge P&L, Burn & Runway'!G17="","",'Kedge P&L, Burn & Runway'!G17>0))="",FALSE,IF(ISERROR('Kedge P&L, Burn & Runway'!G17>0),'Kedge P&L, Burn & Runway'!G17>0,IF('Kedge P&L, Burn & Runway'!G17="","",'Kedge P&L, Burn & Runway'!G17>0))),'Kedge P&L, Burn & Runway'!G17/'Kedge P&L, Burn & Runway'!G15,0),"") | H19: =IF(IF(IF(ISERROR('Kedge P&L, Burn & Runway'!H15>0),'Kedge P&L, Burn & Runway'!H15>0,IF('Kedge P&L, Burn & Runway'!H15="","",'Kedge P&L, Burn & Runway'!H15>0))="",FALSE,IF(ISERROR('Kedge P&L, Burn & Runway'!H15>0),'Kedge P&L, Burn & Runway'!H15>0,IF('Kedge P&L, Burn & Runway'!H15="","",'Kedge P&L, Burn & Runway'!H15>0))),IF(IF(IF(ISERROR('Kedge P&L, Burn & Runway'!H17>0),'Kedge P&L, Burn & Runway'!H17>0,IF('Kedge P&L, Burn & Runway'!H17="","",'Kedge P&L, Burn & Runway'!H17>0))="",FALSE,IF(ISERROR('Kedge P&L, Burn & Runway'!H17>0),'Kedge P&L, Burn & Runway'!H17>0,IF('Kedge P&L, Burn & Runway'!H17="","",'Kedge P&L, Burn & Runway'!H17>0))),'Kedge P&L, Burn & Runway'!H17/'Kedge P&L, Burn & Runway'!H15,0),"") | I19: =IF(IF(IF(ISERROR('Kedge P&L, Burn & Runway'!I15>0),'Kedge P&L, Burn & Runway'!I15>0,IF('Kedge P&L, Burn & Runway'!I15="","",'Kedge P&L, Burn & Runway'!I15>0))="",FALSE,IF(ISERROR('Kedge P&L, Burn & Runway'!I15>0),'Kedge P&L, Burn & Runway'!I15>0,IF('Kedge P&L, Burn & Runway'!I15="","",'Kedge P&L, Burn & Runway'!I15>0))),IF(IF(IF(ISERROR('Kedge P&L, Burn & Runway'!I17>0),'Kedge P&L, Burn & Runway'!I17>0,IF('Kedge P&L, Burn & Runway'!I17="","",'Kedge P&L, Burn & Runway'!I17>0))="",FALSE,IF(ISERROR('Kedge P&L, Burn & Runway'!I17>0),'Kedge P&L, Burn & Runway'!I17>0,IF('Kedge P&L, Burn & Runway'!I17="","",'Kedge P&L, Burn & Runway'!I17>0))),'Kedge P&L, Burn & Runway'!I17/'Kedge P&L, Burn & Runway'!I15,0),"") | ... Y19: =IF(IF(IF(ISERROR('Kedge P&L, Burn & Runway'!Y15>0),'Kedge P&L, Burn & Runway'!Y15>0,IF('Kedge P&L, Burn & Runway'!Y15="","",'Kedge P&L, Burn & Runway'!Y15>0))="",FALSE,IF(ISERROR('Kedge P&L, Burn & Runway'!Y15>0),'Kedge P&L, Burn & Runway'!Y15>0,IF('Kedge P&L, Burn & Runway'!Y15="","",'Kedge P&L, Burn & Runway'!Y15>0))),IF(IF(IF(ISERROR('Kedge P&L, Burn & Runway'!Y17>0),'Kedge P&L, Burn & Runway'!Y17>0,IF('Kedge P&L, Burn & Runway'!Y17="","",'Kedge P&L, Burn & Runway'!Y17>0))="",FALSE,IF(ISERROR('Kedge P&L, Burn & Runway'!Y17>0),'Kedge P&L, Burn & Runway'!Y17>0,IF('Kedge P&L, Burn & Runway'!Y17="","",'Kedge P&L, Burn & Runway'!Y17>0))),'Kedge P&L, Burn & Runway'!Y17/'Kedge P&L, Burn & Runway'!Y15,0),"")

Sheet Model inputs
A1: Model inputs
A2: Integration values are aggregated snapshots; raw source records are not included.
A4: Variables
A5: Variable / segment | B5: 2026-09 | C5: 2026-10 | D5: 2026-11 | E5: 2026-12 | F5: 2027-01 | G5: 2027-02 | H5: 2027-03 | I5: 2027-04 | J5: 2027-05 | K5: 2027-06 | L5: 2027-07 | M5: 2027-08 | N5: 2027-09 | O5: 2027-10 | P5: 2027-11 | Q5: 2027-12 | R5: 2028-01 | S5: 2028-02 | T5: 2028-03 | U5: 2028-04 | V5: 2028-05 | W5: 2028-06 | X5: 2028-07 | Y5: 2028-08 | Z5: 2028-09 | AA5: Value | AB5: 2026-01 | AC5: 2026-02 | AD5: 2026-03 | AE5: 2026-04 | AF5: 2026-05 | AG5: 2026-06 | AH5: 2026-07 | AI5: 2026-08
A6: AI model costs | B6: 0 | C6: ='Model inputs'!C14*'Model inputs'!AA16 -> 40.5 | D6: ='Model inputs'!D14*'Model inputs'!AA16 -> 133.41176 | E6: ='Model inputs'!E14*'Model inputs'!AA16 -> 226.32353 | F6: ='Model inputs'!F14*'Model inputs'!AA16 -> 319.23529 | G6: ='Model inputs'!G14*'Model inputs'!AA16 -> 412.14706 | H6: ='Model inputs'!H14*'Model inputs'!AA16 -> 505.05882 | I6: ='Model inputs'!I14*'Model inputs'!AA16 -> 597.97059 | J6: ='Model inputs'!J14*'Model inputs'!AA16 -> 690.88235 | K6: ='Model inputs'!K14*'Model inputs'!AA16 -> 783.79412 | L6: ='Model inputs'!L14*'Model inputs'!AA16 -> 876.70588 | M6: ='Model inputs'!M14*'Model inputs'!AA16 -> 969.61765 | N6: ='Model inputs'!N14*'Model inputs'!AA16 -> 1062.5294 | O6: ='Model inputs'!O14*'Model inputs'!AA16 -> 1155.4412 | P6: ='Model inputs'!P14*'Model inputs'!AA16 -> 1248.3529 | Q6: ='Model inputs'!Q14*'Model inputs'!AA16 -> 1341.2647 | R6: ='Model inputs'!R14*'Model inputs'!AA16 -> 1434.1765 | S6: ='Model inputs'!S14*'Model inputs'!AA16 -> 1527.0882 | T6: ='Model inputs'!T14*'Model inputs'!AA16 -> 1620 | U6: ='Model inputs'!U14*'Model inputs'!AA16 -> 1620 | V6: ='Model inputs'!V14*'Model inputs'!AA16 -> 1620 | W6: ='Model inputs'!W14*'Model inputs'!AA16 -> 1620 | X6: ='Model inputs'!X14*'Model inputs'!AA16 -> 1620 | Y6: ='Model inputs'!Y14*'Model inputs'!AA16 -> 1620 | Z6: ='Model inputs'!Z14*'Model inputs'!AA16 -> 1620
A7: Cash balance | B7: =IF('Model inputs'!AA31="","",'Model inputs'!AA31) -> 0 | C7: ='Model inputs'!B7-'Model inputs'!C18+'Model inputs'!C9 -> 632.5 | D7: ='Model inputs'!C7-'Model inputs'!D18+'Model inputs'!D9 -> 3174.8529 | E7: ='Model inputs'!D7-'Model inputs'!E18+'Model inputs'!E9 -> 7627.0588 | F7: ='Model inputs'!E7-'Model inputs'!F18+'Model inputs'!F9 -> 13989.118 | G7: ='Model inputs'!F7-'Model inputs'!G18+'Model inputs'!G9 -> 22261.029 | H7: ='Model inputs'!G7-'Model inputs'!H18+'Model inputs'!H9 -> 32442.794 | I7: ='Model inputs'!H7-'Model inputs'!I18+'Model inputs'!I9 -> 36534.412 | J7: ='Model inputs'!I7-'Model inputs'!J18+'Model inputs'!J9 -> 42535.882 | ... Z7: ='Model inputs'!Y7-'Model inputs'!Z18+'Model inputs'!Z9 -> 358192.5
A8: Cost of goods sold | B8: 0 | C8: ='Model inputs'!C6+'Model inputs'!C21 -> 67.5 | D8: ='Model inputs'!D6+'Model inputs'!D21 -> 222.35294 | E8: ='Model inputs'!E6+'Model inputs'!E21 -> 377.20588 | F8: ='Model inputs'!F6+'Model inputs'!F21 -> 532.05882 | G8: ='Model inputs'!G6+'Model inputs'!G21 -> 686.91176 | H8: ='Model inputs'!H6+'Model inputs'!H21 -> 841.76471 | I8: ='Model inputs'!I6+'Model inputs'!I21 -> 996.61765 | J8: ='Model inputs'!J6+'Model inputs'!J21 -> 1151.4706 | ... Z8: ='Model inputs'!Z6+'Model inputs'!Z21 -> 2700
A9: Equity raised | B9: 0 | C9: 0 | D9: 0 | E9: 0 | F9: 0 | G9: 0 | H9: 0 | I9: ='Kedge P&L, Burn & Runway'!H16 -> 0 | J9: 0 | K9: 0 | L9: 0 | M9: 0 | N9: 0 | O9: 0 | P9: 0 | Q9: 0 | R9: 0 | S9: 0 | T9: 0 | U9: 0 | V9: 0 | W9: 0 | X9: 0 | Y9: 0 | Z9: 0
A10: Founder monthly salary | AA10: =4000 -> 4000
A11: Founder salaries | B11: 0 | C11: =IF(IF(IF(ISERROR('Model inputs'!C17>'Model inputs'!AA27),'Model inputs'!C17>'Model inputs'!AA27,IF(OR('Model inputs'!C17="",'Model inputs'!AA27=""),"",'Model inputs'!C17>'Model inputs'!AA27))="",FALSE,IF(ISERROR('Model inputs'!C17>'Model inputs'!AA27),'Model inputs'!C17>'Model inputs'!AA27,IF(OR('Model inputs'!C17="",'Model inputs'!AA27=""),"",'Model inputs'!C17>'Model inputs'!AA27))),'Model inputs'!AA12*'Model inputs'!AA10,0) -> 0 | D11: =IF(IF(IF(ISERROR('Model inputs'!D17>'Model inputs'!AA27),'Model inputs'!D17>'Model inputs'!AA27,IF(OR('Model inputs'!D17="",'Model inputs'!AA27=""),"",'Model inputs'!D17>'Model inputs'!AA27))="",FALSE,IF(ISERROR('Model inputs'!D17>'Model inputs'!AA27),'Model inputs'!D17>'Model inputs'!AA27,IF(OR('Model inputs'!D17="",'Model inputs'!AA27=""),"",'Model inputs'!D17>'Model inputs'!AA27))),'Model inputs'!AA12*'Model inputs'!AA10,0) -> 0 | E11: =IF(IF(IF(ISERROR('Model inputs'!E17>'Model inputs'!AA27),'Model inputs'!E17>'Model inputs'!AA27,IF(OR('Model inputs'!E17="",'Model inputs'!AA27=""),"",'Model inputs'!E17>'Model inputs'!AA27))="",FALSE,IF(ISERROR('Model inputs'!E17>'Model inputs'!AA27),'Model inputs'!E17>'Model inputs'!AA27,IF(OR('Model inputs'!E17="",'Model inputs'!AA27=""),"",'Model inputs'!E17>'Model inputs'!AA27))),'Model inputs'!AA12*'Model inputs'!AA10,0) -> 0 | F11: =IF(IF(IF(ISERROR('Model inputs'!F17>'Model inputs'!AA27),'Model inputs'!F17>'Model inputs'!AA27,IF(OR('Model inputs'!F17="",'Model inputs'!AA27=""),"",'Model inputs'!F17>'Model inputs'!AA27))="",FALSE,IF(ISERROR('Model inputs'!F17>'Model inputs'!AA27),'Model inputs'!F17>'Model inputs'!AA27,IF(OR('Model inputs'!F17="",'Model inputs'!AA27=""),"",'Model inputs'!F17>'Model inputs'!AA27))),'Model inputs'!AA12*'Model inputs'!AA10,0) -> 0 | G11: =IF(IF(IF(ISERROR('Model inputs'!G17>'Model inputs'!AA27),'Model inputs'!G17>'Model inputs'!AA27,IF(OR('Model inputs'!G17="",'Model inputs'!AA27=""),"",'Model inputs'!G17>'Model inputs'!AA27))="",FALSE,IF(ISERROR('Model inputs'!G17>'Model inputs'!AA27),'Model inputs'!G17>'Model inputs'!AA27,IF(OR('Model inputs'!G17="",'Model inputs'!AA27=""),"",'Model inputs'!G17>'Model inputs'!AA27))),'Model inputs'!AA12*'Model inputs'!AA10,0) -> 0 | H11: =IF(IF(IF(ISERROR('Model inputs'!H17>'Model inputs'!AA27),'Model inputs'!H17>'Model inputs'!AA27,IF(OR('Model inputs'!H17="",'Model inputs'!AA27=""),"",'Model inputs'!H17>'Model inputs'!AA27))="",FALSE,IF(ISERROR('Model inputs'!H17>'Model inputs'!AA27),'Model inputs'!H17>'Model inputs'!AA27,IF(OR('Model inputs'!H17="",'Model inputs'!AA27=""),"",'Model inputs'!H17>'Model inputs'!AA27))),'Model inputs'!AA12*'Model inputs'!AA10,0) -> 0 | I11: =IF(IF(IF(ISERROR('Model inputs'!I17>'Model inputs'!AA27),'Model inputs'!I17>'Model inputs'!AA27,IF(OR('Model inputs'!I17="",'Model inputs'!AA27=""),"",'Model inputs'!I17>'Model inputs'!AA27))="",FALSE,IF(ISERROR('Model inputs'!I17>'Model inputs'!AA27),'Model inputs'!I17>'Model inputs'!AA27,IF(OR('Model inputs'!I17="",'Model inputs'!AA27=""),"",'Model inputs'!I17>'Model inputs'!AA27))),'Model inputs'!AA12*'Model inputs'!AA10,0) -> 8000 | J11: =IF(IF(IF(ISERROR('Model inputs'!J17>'Model inputs'!AA27),'Model inputs'!J17>'Model inputs'!AA27,IF(OR('Model inputs'!J17="",'Model inputs'!AA27=""),"",'Model inputs'!J17>'Model inputs'!AA27))="",FALSE,IF(ISERROR('Model inputs'!J17>'Model inputs'!AA27),'Model inputs'!J17>'Model inputs'!AA27,IF(OR('Model inputs'!J17="",'Model inputs'!AA27=""),"",'Model inputs'!J17>'Model inputs'!AA27))),'Model inputs'!AA12*'Model inputs'!AA10,0) -> 8000 | K11: =IF(IF(IF(ISERROR('Model inputs'!K17>'Model inputs'!AA27),'Model inputs'!K17>'Model inputs'!AA27,IF(OR('Model inputs'!K17="",'Model inputs'!AA27=""),"",'Model inputs'!K17>'Model inputs'!AA27))="",FALSE,IF(ISERROR('Model inputs'!K17>'Model inputs'!AA27),'Model inputs'!K17>'Model inputs'!AA27,IF(OR('Model inputs'!K17="",'Model inputs'!AA27=""),"",'Model inputs'!K17>'Model inputs'!AA27))),'Model inputs'!AA12*'Model inputs'!AA10,0) -> 8000 | L11: =IF(IF(IF(ISERROR('Model inputs'!L17>'Model inputs'!AA27),'Model inputs'!L17>'Model inputs'!AA27,IF(OR('Model inputs'!L17="",'Model inputs'!AA27=""),"",'Model inputs'!L17>'Model inputs'!AA27))="",FALSE,IF(ISERROR('Model inputs'!L17>'Model inputs'!AA27),'Model inputs'!L17>'Model inputs'!AA27,IF(OR('Model inputs'!L17="",'Model inputs'!AA27=""),"",'Model inputs'!L17>'Model inputs'!AA27))),'Model inputs'!AA12*'Model inputs'!AA10,0) -> 8000 | M11: =IF(IF(IF(ISERROR('Model inputs'!M17>'Model inputs'!AA27),'Model inputs'!M17>'Model inputs'!AA27,IF(OR('Model inputs'!M17="",'Model inputs'!AA27=""),"",'Model inputs'!M17>'Model inputs'!AA27))="",FALSE,IF(ISERROR('Model inputs'!M17>'Model inputs'!AA27),'Model inputs'!M17>'Model inputs'!AA27,IF(OR('Model inputs'!M17="",'Model inputs'!AA27=""),"",'Model inputs'!M17>'Model inputs'!AA27))),'Model inputs'!AA12*'Model inputs'!AA10,0) -> 8000 | N11: =IF(IF(IF(ISERROR('Model inputs'!N17>'Model inputs'!AA27),'Model inputs'!N17>'Model inputs'!AA27,IF(OR('Model inputs'!N17="",'Model inputs'!AA27=""),"",'Model inputs'!N17>'Model inputs'!AA27))="",FALSE,IF(ISERROR('Model inputs'!N17>'Model inputs'!AA27),'Model inputs'!N17>'Model inputs'!AA27,IF(OR('Model inputs'!N17="",'Model inputs'!AA27=""),"",'Model inputs'!N17>'Model inputs'!AA27))),'Model inputs'!AA12*'Model inputs'!AA10,0) -> 8000 | O11: =IF(IF(IF(ISERROR('Model inputs'!O17>'Model inputs'!AA27),'Model inputs'!O17>'Model inputs'!AA27,IF(OR('Model inputs'!O17="",'Model inputs'!AA27=""),"",'Model inputs'!O17>'Model inputs'!AA27))="",FALSE,IF(ISERROR('Model inputs'!O17>'Model inputs'!AA27),'Model inputs'!O17>'Model inputs'!AA27,IF(OR('Model inputs'!O17="",'Model inputs'!AA27=""),"",'Model inputs'!O17>'Model inputs'!AA27))),'Model inputs'!AA12*'Model inputs'!AA10,0) -> 8000 | P11: =IF(IF(IF(ISERROR('Model inputs'!P17>'Model inputs'!AA27),'Model inputs'!P17>'Model inputs'!AA27,IF(OR('Model inputs'!P17="",'Model inputs'!AA27=""),"",'Model inputs'!P17>'Model inputs'!AA27))="",FALSE,IF(ISERROR('Model inputs'!P17>'Model inputs'!AA27),'Model inputs'!P17>'Model inputs'!AA27,IF(OR('Model inputs'!P17="",'Model inputs'!AA27=""),"",'Model inputs'!P17>'Model inputs'!AA27))),'Model inputs'!AA12*'Model inputs'!AA10,0) -> 8000 | Q11: =IF(IF(IF(ISERROR('Model inputs'!Q17>'Model inputs'!AA27),'Model inputs'!Q17>'Model inputs'!AA27,IF(OR('Model inputs'!Q17="",'Model inputs'!AA27=""),"",'Model inputs'!Q17>'Model inputs'!AA27))="",FALSE,IF(ISERROR('Model inputs'!Q17>'Model inputs'!AA27),'Model inputs'!Q17>'Model inputs'!AA27,IF(OR('Model inputs'!Q17="",'Model inputs'!AA27=""),"",'Model inputs'!Q17>'Model inputs'!AA27))),'Model inputs'!AA12*'Model inputs'!AA10,0) -> 8000 | R11: =IF(IF(IF(ISERROR('Model inputs'!R17>'Model inputs'!AA27),'Model inputs'!R17>'Model inputs'!AA27,IF(OR('Model inputs'!R17="",'Model inputs'!AA27=""),"",'Model inputs'!R17>'Model inputs'!AA27))="",FALSE,IF(ISERROR('Model inputs'!R17>'Model inputs'!AA27),'Model inputs'!R17>'Model inputs'!AA27,IF(OR('Model inputs'!R17="",'Model inputs'!AA27=""),"",'Model inputs'!R17>'Model inputs'!AA27))),'Model inputs'!AA12*'Model inputs'!AA10,0) -> 8000 | S11: =IF(IF(IF(ISERROR('Model inputs'!S17>'Model inputs'!AA27),'Model inputs'!S17>'Model inputs'!AA27,IF(OR('Model inputs'!S17="",'Model inputs'!AA27=""),"",'Model inputs'!S17>'Model inputs'!AA27))="",FALSE,IF(ISERROR('Model inputs'!S17>'Model inputs'!AA27),'Model inputs'!S17>'Model inputs'!AA27,IF(OR('Model inputs'!S17="",'Model inputs'!AA27=""),"",'Model inputs'!S17>'Model inputs'!AA27))),'Model inputs'!AA12*'Model inputs'!AA10,0) -> 8000 | T11: =IF(IF(IF(ISERROR('Model inputs'!T17>'Model inputs'!AA27),'Model inputs'!T17>'Model inputs'!AA27,IF(OR('Model inputs'!T17="",'Model inputs'!AA27=""),"",'Model inputs'!T17>'Model inputs'!AA27))="",FALSE,IF(ISERROR('Model inputs'!T17>'Model inputs'!AA27),'Model inputs'!T17>'Model inputs'!AA27,IF(OR('Model inputs'!T17="",'Model inputs'!AA27=""),"",'Model inputs'!T17>'Model inputs'!AA27))),'Model inputs'!AA12*'Model inputs'!AA10,0) -> 8000 | U11: =IF(IF(IF(ISERROR('Model inputs'!U17>'Model inputs'!AA27),'Model inputs'!U17>'Model inputs'!AA27,IF(OR('Model inputs'!U17="",'Model inputs'!AA27=""),"",'Model inputs'!U17>'Model inputs'!AA27))="",FALSE,IF(ISERROR('Model inputs'!U17>'Model inputs'!AA27),'Model inputs'!U17>'Model inputs'!AA27,IF(OR('Model inputs'!U17="",'Model inputs'!AA27=""),"",'Model inputs'!U17>'Model inputs'!AA27))),'Model inputs'!AA12*'Model inputs'!AA10,0) -> 8000 | V11: =IF(IF(IF(ISERROR('Model inputs'!V17>'Model inputs'!AA27),'Model inputs'!V17>'Model inputs'!AA27,IF(OR('Model inputs'!V17="",'Model inputs'!AA27=""),"",'Model inputs'!V17>'Model inputs'!AA27))="",FALSE,IF(ISERROR('Model inputs'!V17>'Model inputs'!AA27),'Model inputs'!V17>'Model inputs'!AA27,IF(OR('Model inputs'!V17="",'Model inputs'!AA27=""),"",'Model inputs'!V17>'Model inputs'!AA27))),'Model inputs'!AA12*'Model inputs'!AA10,0) -> 8000 | W11: =IF(IF(IF(ISERROR('Model inputs'!W17>'Model inputs'!AA27),'Model inputs'!W17>'Model inputs'!AA27,IF(OR('Model inputs'!W17="",'Model inputs'!AA27=""),"",'Model inputs'!W17>'Model inputs'!AA27))="",FALSE,IF(ISERROR('Model inputs'!W17>'Model inputs'!AA27),'Model inputs'!W17>'Model inputs'!AA27,IF(OR('Model inputs'!W17="",'Model inputs'!AA27=""),"",'Model inputs'!W17>'Model inputs'!AA27))),'Model inputs'!AA12*'Model inputs'!AA10,0) -> 8000 | X11: =IF(IF(IF(ISERROR('Model inputs'!X17>'Model inputs'!AA27),'Model inputs'!X17>'Model inputs'!AA27,IF(OR('Model inputs'!X17="",'Model inputs'!AA27=""),"",'Model inputs'!X17>'Model inputs'!AA27))="",FALSE,IF(ISERROR('Model inputs'!X17>'Model inputs'!AA27),'Model inputs'!X17>'Model inputs'!AA27,IF(OR('Model inputs'!X17="",'Model inputs'!AA27=""),"",'Model inputs'!X17>'Model inputs'!AA27))),'Model inputs'!AA12*'Model inputs'!AA10,0) -> 8000 | Y11: =IF(IF(IF(ISERROR('Model inputs'!Y17>'Model inputs'!AA27),'Model inputs'!Y17>'Model inputs'!AA27,IF(OR('Model inputs'!Y17="",'Model inputs'!AA27=""),"",'Model inputs'!Y17>'Model inputs'!AA27))="",FALSE,IF(ISERROR('Model inputs'!Y17>'Model inputs'!AA27),'Model inputs'!Y17>'Model inputs'!AA27,IF(OR('Model inputs'!Y17="",'Model inputs'!AA27=""),"",'Model inputs'!Y17>'Model inputs'!AA27))),'Model inputs'!AA12*'Model inputs'!AA10,0) -> 8000 | Z11: =IF(IF(IF(ISERROR('Model inputs'!Z17>'Model inputs'!AA27),'Model inputs'!Z17>'Model inputs'!AA27,IF(OR('Model inputs'!Z17="",'Model inputs'!AA27=""),"",'Model inputs'!Z17>'Model inputs'!AA27))="",FALSE,IF(ISERROR('Model inputs'!Z17>'Model inputs'!AA27),'Model inputs'!Z17>'Model inputs'!AA27,IF(OR('Model inputs'!Z17="",'Model inputs'!AA27=""),"",'Model inputs'!Z17>'Model inputs'!AA27))),'Model inputs'!AA12*'Model inputs'!AA10,0) -> 8000
A12: Founders | AA12: =2 -> 2
A13: Funding needed to date | B13: =0 -> 0 | C13: =IF(IF(IF(ISERROR(-'Model inputs'!C7>'Model inputs'!B13),-'Model inputs'!C7>'Model inputs'!B13,IF('Model inputs'!B13="","",-'Model inputs'!C7>'Model inputs'!B13))="",FALSE,IF(ISERROR(-'Model inputs'!C7>'Model inputs'!B13),-'Model inputs'!C7>'Model inputs'!B13,IF('Model inputs'!B13="","",-'Model inputs'!C7>'Model inputs'!B13))),-'Model inputs'!C7,IF('Model inputs'!B13="","",'Model inputs'!B13)) -> 0 | D13: =IF(IF(IF(ISERROR(-'Model inputs'!D7>'Model inputs'!C13),-'Model inputs'!D7>'Model inputs'!C13,IF('Model inputs'!C13="","",-'Model inputs'!D7>'Model inputs'!C13))="",FALSE,IF(ISERROR(-'Model inputs'!D7>'Model inputs'!C13),-'Model inputs'!D7>'Model inputs'!C13,IF('Model inputs'!C13="","",-'Model inputs'!D7>'Model inputs'!C13))),-'Model inputs'!D7,IF('Model inputs'!C13="","",'Model inputs'!C13)) -> 0 | E13: =IF(IF(IF(ISERROR(-'Model inputs'!E7>'Model inputs'!D13),-'Model inputs'!E7>'Model inputs'!D13,IF('Model inputs'!D13="","",-'Model inputs'!E7>'Model inputs'!D13))="",FALSE,IF(ISERROR(-'Model inputs'!E7>'Model inputs'!D13),-'Model inputs'!E7>'Model inputs'!D13,IF('Model inputs'!D13="","",-'Model inputs'!E7>'Model inputs'!D13))),-'Model inputs'!E7,IF('Model inputs'!D13="","",'Model inputs'!D13)) -> 0 | F13: =IF(IF(IF(ISERROR(-'Model inputs'!F7>'Model inputs'!E13),-'Model inputs'!F7>'Model inputs'!E13,IF('Model inputs'!E13="","",-'Model inputs'!F7>'Model inputs'!E13))="",FALSE,IF(ISERROR(-'Model inputs'!F7>'Model inputs'!E13),-'Model inputs'!F7>'Model inputs'!E13,IF('Model inputs'!E13="","",-'Model inputs'!F7>'Model inputs'!E13))),-'Model inputs'!F7,IF('Model inputs'!E13="","",'Model inputs'!E13)) -> 0 | G13: =IF(IF(IF(ISERROR(-'Model inputs'!G7>'Model inputs'!F13),-'Model inputs'!G7>'Model inputs'!F13,IF('Model inputs'!F13="","",-'Model inputs'!G7>'Model inputs'!F13))="",FALSE,IF(ISERROR(-'Model inputs'!G7>'Model inputs'!F13),-'Model inputs'!G7>'Model inputs'!F13,IF('Model inputs'!F13="","",-'Model inputs'!G7>'Model inputs'!F13))),-'Model inputs'!G7,IF('Model inputs'!F13="","",'Model inputs'!F13)) -> 0 | H13: =IF(IF(IF(ISERROR(-'Model inputs'!H7>'Model inputs'!G13),-'Model inputs'!H7>'Model inputs'!G13,IF('Model inputs'!G13="","",-'Model inputs'!H7>'Model inputs'!G13))="",FALSE,IF(ISERROR(-'Model inputs'!H7>'Model inputs'!G13),-'Model inputs'!H7>'Model inputs'!G13,IF('Model inputs'!G13="","",-'Model inputs'!H7>'Model inputs'!G13))),-'Model inputs'!H7,IF('Model inputs'!G13="","",'Model inputs'!G13)) -> 0 | I13: =IF(IF(IF(ISERROR(-'Model inputs'!I7>'Model inputs'!H13),-'Model inputs'!I7>'Model inputs'!H13,IF('Model inputs'!H13="","",-'Model inputs'!I7>'Model inputs'!H13))="",FALSE,IF(ISERROR(-'Model inputs'!I7>'Model inputs'!H13),-'Model inputs'!I7>'Model inputs'!H13,IF('Model inputs'!H13="","",-'Model inputs'!I7>'Model inputs'!H13))),-'Model inputs'!I7,IF('Model inputs'!H13="","",'Model inputs'!H13)) -> 0 | J13: =IF(IF(IF(ISERROR(-'Model inputs'!J7>'Model inputs'!I13),-'Model inputs'!J7>'Model inputs'!I13,IF('Model inputs'!I13="","",-'Model inputs'!J7>'Model inputs'!I13))="",FALSE,IF(ISERROR(-'Model inputs'!J7>'Model inputs'!I13),-'Model inputs'!J7>'Model inputs'!I13,IF('Model inputs'!I13="","",-'Model inputs'!J7>'Model inputs'!I13))),-'Model inputs'!J7,IF('Model inputs'!I13="","",'Model inputs'!I13)) -> 0 | ... Z13: =IF(IF(IF(ISERROR(-'Model inputs'!Z7>'Model inputs'!Y13),-'Model inputs'!Z7>'Model inputs'!Y13,IF('Model inputs'!Y13="","",-'Model inputs'!Z7>'Model inputs'!Y13))="",FALSE,IF(ISERROR(-'Model inputs'!Z7>'Model inputs'!Y13),-'Model inputs'!Z7>'Model inputs'!Y13,IF('Model inputs'!Y13="","",-'Model inputs'!Z7>'Model inputs'!Y13))),-'Model inputs'!Z7,IF('Model inputs'!Y13="","",'Model inputs'!Y13)) -> 0
A14: Green PRs | B14: 0 | C14: ='Model inputs'!C28*'Model inputs'!AA29 -> 90 | D14: ='Model inputs'!D28*'Model inputs'!AA29 -> 296.47059 | E14: ='Model inputs'!E28*'Model inputs'!AA29 -> 502.94118 | F14: ='Model inputs'!F28*'Model inputs'!AA29 -> 709.41176 | G14: ='Model inputs'!G28*'Model inputs'!AA29 -> 915.88235 | H14: ='Model inputs'!H28*'Model inputs'!AA29 -> 1122.3529 | I14: ='Model inputs'!I28*'Model inputs'!AA29 -> 1328.8235 | J14: ='Model inputs'!J28*'Model inputs'!AA29 -> 1535.2941 | K14: ='Model inputs'!K28*'Model inputs'!AA29 -> 1741.7647 | L14: ='Model inputs'!L28*'Model inputs'!AA29 -> 1948.2353 | M14: ='Model inputs'!M28*'Model inputs'!AA29 -> 2154.7059 | N14: ='Model inputs'!N28*'Model inputs'!AA29 -> 2361.1765 | O14: ='Model inputs'!O28*'Model inputs'!AA29 -> 2567.6471 | P14: ='Model inputs'!P28*'Model inputs'!AA29 -> 2774.1176 | Q14: ='Model inputs'!Q28*'Model inputs'!AA29 -> 2980.5882 | R14: ='Model inputs'!R28*'Model inputs'!AA29 -> 3187.0588 | S14: ='Model inputs'!S28*'Model inputs'!AA29 -> 3393.5294 | T14: ='Model inputs'!T28*'Model inputs'!AA29 -> 3600 | U14: ='Model inputs'!U28*'Model inputs'!AA29 -> 3600 | V14: ='Model inputs'!V28*'Model inputs'!AA29 -> 3600 | W14: ='Model inputs'!W28*'Model inputs'!AA29 -> 3600 | X14: ='Model inputs'!X28*'Model inputs'!AA29 -> 3600 | Y14: ='Model inputs'!Y28*'Model inputs'!AA29 -> 3600 | Z14: ='Model inputs'!Z28*'Model inputs'!AA29 -> 3600
A15: Gross profit | B15: 0 | C15: ='Model inputs'!C24-'Model inputs'!C8 -> 832.5 | D15: ='Model inputs'!D24-'Model inputs'!D8 -> 2742.3529 | E15: ='Model inputs'!E24-'Model inputs'!E8 -> 4652.2059 | F15: ='Model inputs'!F24-'Model inputs'!F8 -> 6562.0588 | G15: ='Model inputs'!G24-'Model inputs'!G8 -> 8471.9118 | H15: ='Model inputs'!H24-'Model inputs'!H8 -> 10381.765 | I15: ='Model inputs'!I24-'Model inputs'!I8 -> 12291.618 | J15: ='Model inputs'!J24-'Model inputs'!J8 -> 14201.471 | ... Z15: ='Model inputs'!Z24-'Model inputs'!Z8 -> 33300
A16: Model cost per green PR | AA16: =0.45 -> 0.45
A17: Month number | B17: =0 -> 0 | C17: ='Model inputs'!B17+1 -> 1 | D17: ='Model inputs'!C17+1 -> 2 | E17: ='Model inputs'!D17+1 -> 3 | F17: ='Model inputs'!E17+1 -> 4 | G17: ='Model inputs'!F17+1 -> 5 | H17: ='Model inputs'!G17+1 -> 6 | I17: ='Model inputs'!H17+1 -> 7 | J17: ='Model inputs'!I17+1 -> 8 | ... Z17: ='Model inputs'!Y17+1 -> 24
A18: Net burn | B18: 0 | C18: =-'Model inputs'!C20 -> -632.5 | D18: =-'Model inputs'!D20 -> -2542.3529 | E18: =-'Model inputs'!E20 -> -4452.2059 | F18: =-'Model inputs'!F20 -> -6362.0588 | G18: =-'Model inputs'!G20 -> -8271.9118 | H18: =-'Model inputs'!H20 -> -10181.765 | I18: =-'Model inputs'!I20 -> -4091.6176 | J18: =-'Model inputs'!J20 -> -6001.4706 | ... Z18: =-'Model inputs'!Z20 -> -25100
A19: Operating expenses | B19: 0 | C19: ='Model inputs'!C11+'Model inputs'!C25 -> 200 | D19: ='Model inputs'!D11+'Model inputs'!D25 -> 200 | E19: ='Model inputs'!E11+'Model inputs'!E25 -> 200 | F19: ='Model inputs'!F11+'Model inputs'!F25 -> 200 | G19: ='Model inputs'!G11+'Model inputs'!G25 -> 200 | H19: ='Model inputs'!H11+'Model inputs'!H25 -> 200 | I19: ='Model inputs'!I11+'Model inputs'!I25 -> 8200 | J19: ='Model inputs'!J11+'Model inputs'!J25 -> 8200 | ... Z19: ='Model inputs'!Z11+'Model inputs'!Z25 -> 8200
A20: Operating income | B20: 0 | C20: ='Model inputs'!C15-'Model inputs'!C19 -> 632.5 | D20: ='Model inputs'!D15-'Model inputs'!D19 -> 2542.3529 | E20: ='Model inputs'!E15-'Model inputs'!E19 -> 4452.2059 | F20: ='Model inputs'!F15-'Model inputs'!F19 -> 6362.0588 | G20: ='Model inputs'!G15-'Model inputs'!G19 -> 8271.9118 | H20: ='Model inputs'!H15-'Model inputs'!H19 -> 10181.765 | I20: ='Model inputs'!I15-'Model inputs'!I19 -> 4091.6176 | J20: ='Model inputs'!J15-'Model inputs'!J19 -> 6001.4706 | ... Z20: ='Model inputs'!Z15-'Model inputs'!Z19 -> 25100
A21: Payment processing | B21: 0 | C21: ='Model inputs'!C24*'Model inputs'!AA22 -> 27 | D21: ='Model inputs'!D24*'Model inputs'!AA22 -> 88.941176 | E21: ='Model inputs'!E24*'Model inputs'!AA22 -> 150.88235 | F21: ='Model inputs'!F24*'Model inputs'!AA22 -> 212.82353 | G21: ='Model inputs'!G24*'Model inputs'!AA22 -> 274.76471 | H21: ='Model inputs'!H24*'Model inputs'!AA22 -> 336.70588 | I21: ='Model inputs'!I24*'Model inputs'!AA22 -> 398.64706 | J21: ='Model inputs'!J24*'Model inputs'!AA22 -> 460.58824 | K21: ='Model inputs'!K24*'Model inputs'!AA22 -> 522.52941 | L21: ='Model inputs'!L24*'Model inputs'!AA22 -> 584.47059 | M21: ='Model inputs'!M24*'Model inputs'!AA22 -> 646.41176 | N21: ='Model inputs'!N24*'Model inputs'!AA22 -> 708.35294 | O21: ='Model inputs'!O24*'Model inputs'!AA22 -> 770.29412 | P21: ='Model inputs'!P24*'Model inputs'!AA22 -> 832.23529 | Q21: ='Model inputs'!Q24*'Model inputs'!AA22 -> 894.17647 | R21: ='Model inputs'!R24*'Model inputs'!AA22 -> 956.11765 | S21: ='Model inputs'!S24*'Model inputs'!AA22 -> 1018.0588 | T21: ='Model inputs'!T24*'Model inputs'!AA22 -> 1080 | U21: ='Model inputs'!U24*'Model inputs'!AA22 -> 1080 | V21: ='Model inputs'!V24*'Model inputs'!AA22 -> 1080 | W21: ='Model inputs'!W24*'Model inputs'!AA22 -> 1080 | X21: ='Model inputs'!X24*'Model inputs'!AA22 -> 1080 | Y21: ='Model inputs'!Y24*'Model inputs'!AA22 -> 1080 | Z21: ='Model inputs'!Z24*'Model inputs'!AA22 -> 1080
A22: Payment processing rate | AA22: =0.03 -> 0.03
A23: Price per green PR | AA23: =10 -> 10
